Workbook

Sheet input player
A1: Team Name | B1: Team Tag | C1: Player 1 | D1: Player 2 | E1: Player 3 | F1: Player 4 | G1: Flag
A2: Award | B2: AWD | C2: Alice | D2: Bob | E2: Carol | F2: Dave | G2: ="C:\Users\mapay\Desktop\PUBG LIVE\team_logos\" & '[1]input player'!B2 & ".png" -> C:\Users\mapay\Desktop\PUBG LIVE\team_logos\AWD.png
A3: BOSS | B3: BOS | C3: Eva | D3: Flank | E3: Skilp | F3: Fal | G3: ="C:\Users\mapay\Desktop\PUBG LIVE\team_logos\" & '[1]input player'!B3 & ".png" -> C:\Users\mapay\Desktop\PUBG LIVE\team_logos\BOS.png
A4: NerverDIe | B4: NVD | C4: figma | D4: SSa2 | E4: TTs | F4: 5555W | G4: ="C:\Users\mapay\Desktop\PUBG LIVE\team_logos\" & '[1]input player'!B4 & ".png" -> C:\Users\mapay\Desktop\PUBG LIVE\team_logos\NVD.png
A5: Skibidy | B5: SBD | C5: dsa | D5: hgaaw | E5: Wsxa | F5: savfa | G5: ="C:\Users\mapay\Desktop\PUBG LIVE\team_logos\" & '[1]input player'!B5 & ".png" -> C:\Users\mapay\Desktop\PUBG LIVE\team_logos\SBD.png
A6: Raddom | B6: RD | C6: 1111 | D6: opsSS | E6: Navaw | F6: XIVVV | G6: ="C:\Users\mapay\Desktop\PUBG LIVE\team_logos\" & '[1]input player'!B6 & ".png" -> C:\Users\mapay\Desktop\PUBG LIVE\team_logos\RD.png
A7: SaSaRaSa | B7: SSRS | C7: gagw | D7: dwasdw | E7: fgwagfwa | F7: wfwafwafaw | G7: ="C:\Users\mapay\Desktop\PUBG LIVE\team_logos\" & '[1]input player'!B7 & ".png" -> C:\Users\mapay\Desktop\PUBG LIVE\team_logos\SSRS.png
A8: Onpara | B8: OP | C8: sdadsa | D8: gaaga | E8: ssdsa | F8: acxzcw | G8: ="C:\Users\mapay\Desktop\PUBG LIVE\team_logos\" & '[1]input player'!B8 & ".png" -> C:\Users\mapay\Desktop\PUBG LIVE\team_logos\OP.png
A9: NoXe | B9: NX | C9: wdwad | D9: sdwa | E9: sdaw | F9: adsdwa | G9: ="C:\Users\mapay\Desktop\PUBG LIVE\team_logos\" & '[1]input player'!B9 & ".png" -> C:\Users\mapay\Desktop\PUBG LIVE\team_logos\NX.png
A10: SEEBRAZ | B10: SBZ | C10: sdawds | D10: adwads | E10: adwads | F10: adwadsa | G10: ="C:\Users\mapay\Desktop\PUBG LIVE\team_logos\" & '[1]input player'!B10 & ".png" -> C:\Users\mapay\Desktop\PUBG LIVE\team_logos\SBZ.png
A11: ff | B11: FF | C11: sdawds | D11: adwads | E11: adwads | F11: adwadsa | G11: ="C:\Users\mapay\Desktop\PUBG LIVE\team_logos\" & '[1]input player'!B11 & ".png" -> C:\Users\mapay\Desktop\PUBG LIVE\team_logos\SBZ.png
A12: sdfsdf | B12: SDF | C12: sdawds | D12: adwads | E12: adwads | F12: adwadsa | G12: ="C:\Users\mapay\Desktop\PUBG LIVE\team_logos\" & '[1]input player'!B12 & ".png" -> C:\Users\mapay\Desktop\PUBG LIVE\team_logos\SBZ.png
A13: HHHH | B13: HHH | C13: sdawds | D13: adwads | E13: adwads | F13: adwadsa | G13: ="C:\Users\mapay\Desktop\PUBG LIVE\team_logos\" & '[1]input player'!B13 & ".png" -> C:\Users\mapay\Desktop\PUBG LIVE\team_logos\SBZ.png
A14: SSEE | B14: SSEE | C14: sdawds | D14: adwads | E14: adwads | F14: adwadsa | G14: ="C:\Users\mapay\Desktop\PUBG LIVE\team_logos\" & '[1]input player'!B14 & ".png" -> C:\Users\mapay\Desktop\PUBG LIVE\team_logos\SBZ.png
A15: rr | B15: RR | C15: sdawds | D15: adwads | E15: adwads | F15: adwadsa | G15: ="C:\Users\mapay\Desktop\PUBG LIVE\team_logos\" & '[1]input player'!B15 & ".png" -> C:\Users\mapay\Desktop\PUBG LIVE\team_logos\RR.png
A16: wwww | B16: www | C16: sdawdsdsad | D16: adasdasdwads | E16: grjadwads | F16: kuyadwadsatyjk | G16: ="C:\Users\mapay\Desktop\PUBG LIVE\team_logos\" & '[1]input player'!B16 & ".png" -> C:\Users\mapay\Desktop\PUBG LIVE\team_logos\www.png
A17: asfasadsd | B17: ASFA | C17: f | D17: adwdf | E17: as | F17: ffff | G17: ="C:\Users\mapay\Desktop\PUBG LIVE\team_logos\" & '[1]input player'!B17 & ".png" -> C:\Users\mapay\Desktop\PUBG LIVE\team_logos\ASFA.png

Sheet map settings

Sheet TEAMLIST
A1: TEAM TAG | B1: TEAM NAME | C1: PLAYER 1 | D1: PLAYER 2 | E1: PLAYER 3 | F1: PLAYER 4
A2: {=IFERROR(INDEX('input player'!B:B, ROW()), "")} -> AWD | B2: {=IFERROR(INDEX('input player'!A:A, ROW()), "")} -> Award | C2: {=IFERROR(INDEX('input player'!C:C, ROW()), "")} -> Alice | D2: {=IFERROR(INDEX('input player'!D:D, ROW()), "")} -> Bob | E2: {=IFERROR(INDEX('input player'!E:E, ROW()), "")} -> Carol | F2: {=IFERROR(INDEX('input player'!F:F, ROW()), "")} -> Dave
A3: {=IFERROR(INDEX('input player'!B:B, ROW()), "")} -> BOS | B3: {=IFERROR(INDEX('input player'!A:A, ROW()), "")} -> BOSS | C3: {=IFERROR(INDEX('input player'!C:C, ROW()), "")} -> Eva | D3: {=IFERROR(INDEX('input player'!D:D, ROW()), "")} -> Flank | E3: {=IFERROR(INDEX('input player'!E:E, ROW()), "")} -> Skilp | F3: {=IFERROR(INDEX('input player'!F:F, ROW()), "")} -> Fal
A4: {=IFERROR(INDEX('input player'!B:B, ROW()), "")} -> NVD | B4: {=IFERROR(INDEX('input player'!A:A, ROW()), "")} -> NerverDIe | C4: {=IFERROR(INDEX('input player'!C:C, ROW()), "")} -> figma | D4: {=IFERROR(INDEX('input player'!D:D, ROW()), "")} -> SSa2 | E4: {=IFERROR(INDEX('input player'!E:E, ROW()), "")} -> TTs | F4: {=IFERROR(INDEX('input player'!F:F, ROW()), "")} -> 5555W
A5: {=IFERROR(INDEX('input player'!B:B, ROW()), "")} -> SBD | B5: {=IFERROR(INDEX('input player'!A:A, ROW()), "")} -> Skibidy | C5: {=IFERROR(INDEX('input player'!C:C, ROW()), "")} -> dsa | D5: {=IFERROR(INDEX('input player'!D:D, ROW()), "")} -> hgaaw | E5: {=IFERROR(INDEX('input player'!E:E, ROW()), "")} -> Wsxa | F5: {=IFERROR(INDEX('input player'!F:F, ROW()), "")} -> savfa
A6: {=IFERROR(INDEX('input player'!B:B, ROW()), "")} -> RD | B6: {=IFERROR(INDEX('input player'!A:A, ROW()), "")} -> Raddom | C6: {=IFERROR(INDEX('input player'!C:C, ROW()), "")} -> 1111 | D6: {=IFERROR(INDEX('input player'!D:D, ROW()), "")} -> opsSS | E6: {=IFERROR(INDEX('input player'!E:E, ROW()), "")} -> Navaw | F6: {=IFERROR(INDEX('input player'!F:F, ROW()), "")} -> XIVVV
A7: {=IFERROR(INDEX('input player'!B:B, ROW()), "")} -> SSRS | B7: {=IFERROR(INDEX('input player'!A:A, ROW()), "")} -> SaSaRaSa | C7: {=IFERROR(INDEX('input player'!C:C, ROW()), "")} -> gagw | D7: {=IFERROR(INDEX('input player'!D:D, ROW()), "")} -> dwasdw | E7: {=IFERROR(INDEX('input player'!E:E, ROW()), "")} -> fgwagfwa | F7: {=IFERROR(INDEX('input player'!F:F, ROW()), "")} -> wfwafwafaw
A8: {=IFERROR(INDEX('input player'!B:B, ROW()), "")} -> OP | B8: {=IFERROR(INDEX('input player'!A:A, ROW()), "")} -> Onpara | C8: {=IFERROR(INDEX('input player'!C:C, ROW()), "")} -> sdadsa | D8: {=IFERROR(INDEX('input player'!D:D, ROW()), "")} -> gaaga | E8: {=IFERROR(INDEX('input player'!E:E, ROW()), "")} -> ssdsa | F8: {=IFERROR(INDEX('input player'!F:F, ROW()), "")} -> acxzcw
A9: {=IFERROR(INDEX('input player'!B:B, ROW()), "")} -> NX | B9: {=IFERROR(INDEX('input player'!A:A, ROW()), "")} -> NoXe | C9: {=IFERROR(INDEX('input player'!C:C, ROW()), "")} -> wdwad | D9: {=IFERROR(INDEX('input player'!D:D, ROW()), "")} -> sdwa | E9: {=IFERROR(INDEX('input player'!E:E, ROW()), "")} -> sdaw | F9: {=IFERROR(INDEX('input player'!F:F, ROW()), "")} -> adsdwa
A10: {=IFERROR(INDEX('input player'!B:B, ROW()), "")} -> SBZ | B10: {=IFERROR(INDEX('input player'!A:A, ROW()), "")} -> SEEBRAZ | C10: {=IFERROR(INDEX('input player'!C:C, ROW()), "")} -> sdawds | D10: {=IFERROR(INDEX('input player'!D:D, ROW()), "")} -> adwads | E10: {=IFERROR(INDEX('input player'!E:E, ROW()), "")} -> adwads | F10: {=IFERROR(INDEX('input player'!F:F, ROW()), "")} -> adwadsa
A11: {=IFERROR(INDEX('input player'!B:B, ROW()), "")} -> FF | B11: {=IFERROR(INDEX('input player'!A:A, ROW()), "")} -> ff | C11: {=IFERROR(INDEX('input player'!C:C, ROW()), "")} -> sdawds | D11: {=IFERROR(INDEX('input player'!D:D, ROW()), "")} -> adwads | E11: {=IFERROR(INDEX('input player'!E:E, ROW()), "")} -> adwads | F11: {=IFERROR(INDEX('input player'!F:F, ROW()), "")} -> adwadsa
A12: {=IFERROR(INDEX('input player'!B:B, ROW()), "")} -> SDF | B12: {=IFERROR(INDEX('input player'!A:A, ROW()), "")} -> sdfsdf | C12: {=IFERROR(INDEX('input player'!C:C, ROW()), "")} -> sdawds | D12: {=IFERROR(INDEX('input player'!D:D, ROW()), "")} -> adwads | E12: {=IFERROR(INDEX('input player'!E:E, ROW()), "")} -> adwads | F12: {=IFERROR(INDEX('input player'!F:F, ROW()), "")} -> adwadsa
A13: {=IFERROR(INDEX('input player'!B:B, ROW()), "")} -> HHH | B13: {=IFERROR(INDEX('input player'!A:A, ROW()), "")} -> HHHH | C13: {=IFERROR(INDEX('input player'!C:C, ROW()), "")} -> sdawds | D13: {=IFERROR(INDEX('input player'!D:D, ROW()), "")} -> adwads | E13: {=IFERROR(INDEX('input player'!E:E, ROW()), "")} -> adwads | F13: {=IFERROR(INDEX('input player'!F:F, ROW()), "")} -> adwadsa
... A17: {=IFERROR(INDEX('input player'!B:B, ROW()), "")} -> ASFA | B17: {=IFERROR(INDEX('input player'!A:A, ROW()), "")} -> asfasadsd | C17: {=IFERROR(INDEX('input player'!C:C, ROW()), "")} -> f | D17: {=IFERROR(INDEX('input player'!D:D, ROW()), "")} -> adwdf | E17: {=IFERROR(INDEX('input player'!E:E, ROW()), "")} -> as | F17: {=IFERROR(INDEX('input player'!F:F, ROW()), "")} -> ffff

Sheet DAY OVERLAY
A1: {='[1]DAY SUMMARY W1D1'!J2:Q17} -> RR | B1: rr | C1: 5 | D1: 0 | E1: 0 | F1: 0 | G1: 5 | H1: 1
A2: RD | B2: Raddom | C2: 3 | D2: 0 | E2: 0 | F2: 0 | G2: 3 | H2: 2
A3: AWD | B3: Award | C3: 1 | D3: 0 | E3: 0 | F3: 0 | G3: 1 | H3: 3
A4: BOS | B4: BOSS | C4: 0 | D4: 0 | E4: 0 | F4: 0 | G4: 0 | H4: 4
A5: NVD | B5: NerverDIe | C5: 0 | D5: 0 | E5: 0 | F5: 0 | G5: 0 | H5: 4
A6: SBD | B6: Skibidy | C6: 0 | D6: 0 | E6: 0 | F6: 0 | G6: 0 | H6: 4
A7: SSRS | B7: SaSaRaSa | C7: 0 | D7: 0 | E7: 0 | F7: 0 | G7: 0 | H7: 4
A8: OP | B8: Onpara | C8: 0 | D8: 0 | E8: 0 | F8: 0 | G8: 0 | H8: 4
A9: NX | B9: NoXe | C9: 0 | D9: 0 | E9: 0 | F9: 0 | G9: 0 | H9: 4
A10: SBZ | B10: SEEBRAZ | C10: 0 | D10: 0 | E10: 0 | F10: 0 | G10: 0 | H10: 4
A11: SBZ | B11: SEEBRAZ | C11: 0 | D11: 0 | E11: 0 | F11: 0 | G11: 0 | H11: 4
A12: SBZ | B12: SEEBRAZ | C12: 0 | D12: 0 | E12: 0 | F12: 0 | G12: 0 | H12: 4
A13: SBZ | B13: SEEBRAZ | C13: 0 | D13: 0 | E13: 0 | F13: 0 | G13: 0 | H13: 4
... A16: ASFA | B16: asfasadsd | C16: 0 | D16: 0 | E16: 0 | F16: 0 | G16: 0 | H16: 4

Sheet DAY SUMMARY W1D1
A1: TEAM ID | B1: TEAM NAME | C1: M1 | D1: M2 | E1: M3 | F1: M4 | G1: TOTAL | H1: RANK
A2: {=INDEX(TEAMLIST!A:A, ROW())} -> AWD | B2: {=INDEX(TEAMLIST!B:B, ROW())} -> Award | C2: =IFERROR(VLOOKUP($A2, W1D1M1!$A:$F, 6, FALSE), 0) -> 1 | D2: =IFERROR(VLOOKUP($A2, W1D1M2!$A:$F, 6, FALSE), 0) -> 0 | E2: =IFERROR(VLOOKUP($A2, W1D1M3!$A:$F, 6, FALSE), 0) -> 0 | F2: =IFERROR(VLOOKUP($A2,#REF!, 6, FALSE), 0) -> 0 | G2: =SUM(C2:F2) -> 1 | H2: =IFERROR(RANK(G2,$G$2:$G$17,0),0) -> 3 | J2: {=_xlfn._xlws.SORT(A2:H17, 8, 1)} -> RR | K2: rr | L2: 5 | M2: 0 | N2: 0 | O2: 0 | P2: 5 | Q2: 1
A3: {=INDEX(TEAMLIST!A:A, ROW())} -> BOS | B3: {=INDEX(TEAMLIST!B:B, ROW())} -> BOSS | C3: =IFERROR(VLOOKUP($A3, W1D1M1!$A:$F, 6, FALSE), 0) -> 0 | D3: =IFERROR(VLOOKUP($A3, W1D1M2!$A:$F, 6, FALSE), 0) -> 0 | E3: =IFERROR(VLOOKUP($A3, W1D1M3!$A:$F, 6, FALSE), 0) -> 0 | F3: =IFERROR(VLOOKUP($A3,#REF!, 6, FALSE), 0) -> 0 | G3: =SUM(C3:F3) -> 0 | H3: =IFERROR(RANK(G3,$G$2:$G$17,0),0) -> 4 | J3: RD | K3: Raddom | L3: 3 | M3: 0 | N3: 0 | O3: 0 | P3: 3 | Q3: 2
A4: {=INDEX(TEAMLIST!A:A, ROW())} -> NVD | B4: {=INDEX(TEAMLIST!B:B, ROW())} -> NerverDIe | C4: =IFERROR(VLOOKUP($A4, W1D1M1!$A:$F, 6, FALSE), 0) -> 0 | D4: =IFERROR(VLOOKUP($A4, W1D1M2!$A:$F, 6, FALSE), 0) -> 0 | E4: =IFERROR(VLOOKUP($A4, W1D1M3!$A:$F, 6, FALSE), 0) -> 0 | F4: =IFERROR(VLOOKUP($A4,#REF!, 6, FALSE), 0) -> 0 | G4: =SUM(C4:F4) -> 0 | H4: =IFERROR(RANK(G4,$G$2:$G$17,0),0) -> 4 | J4: AWD | K4: Award | L4: 1 | M4: 0 | N4: 0 | O4: 0 | P4: 1 | Q4: 3
A5: {=INDEX(TEAMLIST!A:A, ROW())} -> SBD | B5: {=INDEX(TEAMLIST!B:B, ROW())} -> Skibidy | C5: =IFERROR(VLOOKUP($A5, W1D1M1!$A:$F, 6, FALSE), 0) -> 0 | D5: =IFERROR(VLOOKUP($A5, W1D1M2!$A:$F, 6, FALSE), 0) -> 0 | E5: =IFERROR(VLOOKUP($A5, W1D1M3!$A:$F, 6, FALSE), 0) -> 0 | F5: =IFERROR(VLOOKUP($A5,#REF!, 6, FALSE), 0) -> 0 | G5: =SUM(C5:F5) -> 0 | H5: =IFERROR(RANK(G5,$G$2:$G$17,0),0) -> 4 | J5: BOS | K5: BOSS | L5: 0 | M5: 0 | N5: 0 | O5: 0 | P5: 0 | Q5: 4
A6: {=INDEX(TEAMLIST!A:A, ROW())} -> RD | B6: {=INDEX(TEAMLIST!B:B, ROW())} -> Raddom | C6: =IFERROR(VLOOKUP($A6, W1D1M1!$A:$F, 6, FALSE), 0) -> 3 | D6: =IFERROR(VLOOKUP($A6, W1D1M2!$A:$F, 6, FALSE), 0) -> 0 | E6: =IFERROR(VLOOKUP($A6, W1D1M3!$A:$F, 6, FALSE), 0) -> 0 | F6: =IFERROR(VLOOKUP($A6,#REF!, 6, FALSE), 0) -> 0 | G6: =SUM(C6:F6) -> 3 | H6: =IFERROR(RANK(G6,$G$2:$G$17,0),0) -> 2 | J6: NVD | K6: NerverDIe | L6: 0 | M6: 0 | N6: 0 | O6: 0 | P6: 0 | Q6: 4
A7: {=INDEX(TEAMLIST!A:A, ROW())} -> SSRS | B7: {=INDEX(TEAMLIST!B:B, ROW())} -> SaSaRaSa | C7: =IFERROR(VLOOKUP($A7, W1D1M1!$A:$F, 6, FALSE), 0) -> 0 | D7: =IFERROR(VLOOKUP($A7, W1D1M2!$A:$F, 6, FALSE), 0) -> 0 | E7: =IFERROR(VLOOKUP($A7, W1D1M3!$A:$F, 6, FALSE), 0) -> 0 | F7: =IFERROR(VLOOKUP($A7,#REF!, 6, FALSE), 0) -> 0 | G7: =SUM(C7:F7) -> 0 | H7: =IFERROR(RANK(G7,$G$2:$G$17,0),0) -> 4 | J7: SBD | K7: Skibidy | L7: 0 | M7: 0 | N7: 0 | O7: 0 | P7: 0 | Q7: 4
A8: {=INDEX(TEAMLIST!A:A, ROW())} -> OP | B8: {=INDEX(TEAMLIST!B:B, ROW())} -> Onpara | C8: =IFERROR(VLOOKUP($A8, W1D1M1!$A:$F, 6, FALSE), 0) -> 0 | D8: =IFERROR(VLOOKUP($A8, W1D1M2!$A:$F, 6, FALSE), 0) -> 0 | E8: =IFERROR(VLOOKUP($A8, W1D1M3!$A:$F, 6, FALSE), 0) -> 0 | F8: =IFERROR(VLOOKUP($A8,#REF!, 6, FALSE), 0) -> 0 | G8: =SUM(C8:F8) -> 0 | H8: =IFERROR(RANK(G8,$G$2:$G$17,0),0) -> 4 | J8: SSRS | K8: SaSaRaSa | L8: 0 | M8: 0 | N8: 0 | O8: 0 | P8: 0 | Q8: 4
A9: {=INDEX(TEAMLIST!A:A, ROW())} -> NX | B9: {=INDEX(TEAMLIST!B:B, ROW())} -> NoXe | C9: =IFERROR(VLOOKUP($A9, W1D1M1!$A:$F, 6, FALSE), 0) -> 0 | D9: =IFERROR(VLOOKUP($A9, W1D1M2!$A:$F, 6, FALSE), 0) -> 0 | E9: =IFERROR(VLOOKUP($A9, W1D1M3!$A:$F, 6, FALSE), 0) -> 0 | F9: =IFERROR(VLOOKUP($A9,#REF!, 6, FALSE), 0) -> 0 | G9: =SUM(C9:F9) -> 0 | H9: =IFERROR(RANK(G9,$G$2:$G$17,0),0) -> 4 | J9: OP | K9: Onpara | L9: 0 | M9: 0 | N9: 0 | O9: 0 | P9: 0 | Q9: 4
A10: {=INDEX(TEAMLIST!A:A, ROW())} -> SBZ | B10: {=INDEX(TEAMLIST!B:B, ROW())} -> SEEBRAZ | C10: =IFERROR(VLOOKUP($A10, W1D1M1!$A:$F, 6, FALSE), 0) -> 0 | D10: =IFERROR(VLOOKUP($A10, W1D1M2!$A:$F, 6, FALSE), 0) -> 0 | E10: =IFERROR(VLOOKUP($A10, W1D1M3!$A:$F, 6, FALSE), 0) -> 0 | F10: =IFERROR(VLOOKUP($A10,#REF!, 6, FALSE), 0) -> 0 | G10: =SUM(C10:F10) -> 0 | H10: =IFERROR(RANK(G10,$G$2:$G$17,0),0) -> 4 | J10: NX | K10: NoXe | L10: 0 | M10: 0 | N10: 0 | O10: 0 | P10: 0 | Q10: 4
A11: {=INDEX(TEAMLIST!A:A, ROW())} -> FF | B11: {=INDEX(TEAMLIST!B:B, ROW())} -> ff | C11: =IFERROR(VLOOKUP($A11, W1D1M1!$A:$F, 6, FALSE), 0) -> 0 | D11: =IFERROR(VLOOKUP($A11, W1D1M2!$A:$F, 6, FALSE), 0) -> 0 | E11: =IFERROR(VLOOKUP($A11, W1D1M3!$A:$F, 6, FALSE), 0) -> 0 | F11: =IFERROR(VLOOKUP($A11,#REF!, 6, FALSE), 0) -> 0 | G11: =SUM(C11:F11) -> 0 | H11: =IFERROR(RANK(G11,$G$2:$G$17,0),0) -> 4 | J11: SBZ | K11: SEEBRAZ | L11: 0 | M11: 0 | N11: 0 | O11: 0 | P11: 0 | Q11: 4
A12: {=INDEX(TEAMLIST!A:A, ROW())} -> SDF | B12: {=INDEX(TEAMLIST!B:B, ROW())} -> sdfsdf | C12: =IFERROR(VLOOKUP($A12, W1D1M1!$A:$F, 6, FALSE), 0) -> 0 | D12: =IFERROR(VLOOKUP($A12, W1D1M2!$A:$F, 6, FALSE), 0) -> 0 | E12: =IFERROR(VLOOKUP($A12, W1D1M3!$A:$F, 6, FALSE), 0) -> 0 | F12: =IFERROR(VLOOKUP($A12,#REF!, 6, FALSE), 0) -> 0 | G12: =SUM(C12:F12) -> 0 | H12: =IFERROR(RANK(G12,$G$2:$G$17,0),0) -> 4 | J12: FF | K12: ff | L12: 0 | M12: 0 | N12: 0 | O12: 0 | P12: 0 | Q12: 4
A13: {=INDEX(TEAMLIST!A:A, ROW())} -> HHH | B13: {=INDEX(TEAMLIST!B:B, ROW())} -> HHHH | C13: =IFERROR(VLOOKUP($A13, W1D1M1!$A:$F, 6, FALSE), 0) -> 0 | D13: =IFERROR(VLOOKUP($A13, W1D1M2!$A:$F, 6, FALSE), 0) -> 0 | E13: =IFERROR(VLOOKUP($A13, W1D1M3!$A:$F, 6, FALSE), 0) -> 0 | F13: =IFERROR(VLOOKUP($A13,#REF!, 6, FALSE), 0) -> 0 | G13: =SUM(C13:F13) -> 0 | H13: =IFERROR(RANK(G13,$G$2:$G$17,0),0) -> 4 | J13: SDF | K13: sdfsdf | L13: 0 | M13: 0 | N13: 0 | O13: 0 | P13: 0 | Q13: 4
A14: {=INDEX(TEAMLIST!A:A, ROW())} -> SSEE | B14: {=INDEX(TEAMLIST!B:B, ROW())} -> SSEE | C14: =IFERROR(VLOOKUP($A14, W1D1M1!$A:$F, 6, FALSE), 0) -> 0 | D14: =IFERROR(VLOOKUP($A14, W1D1M2!$A:$F, 6, FALSE), 0) -> 0 | E14: =IFERROR(VLOOKUP($A14, W1D1M3!$A:$F, 6, FALSE), 0) -> 0 | F14: =IFERROR(VLOOKUP($A14,#REF!, 6, FALSE), 0) -> 0 | G14: =SUM(C14:F14) -> 0 | H14: =IFERROR(RANK(G14,$G$2:$G$17,0),0) -> 4 | J14: HHH | K14: HHHH | L14: 0 | M14: 0 | N14: 0 | O14: 0 | P14: 0 | Q14: 4
... A17: {=INDEX(TEAMLIST!A:A, ROW())} -> ASFA | B17: {=INDEX(TEAMLIST!B:B, ROW())} -> asfasadsd | C17: =IFERROR(VLOOKUP($A17, W1D1M1!$A:$F, 6, FALSE), 0) -> 0 | D17: =IFERROR(VLOOKUP($A17, W1D1M2!$A:$F, 6, FALSE), 0) -> 0 | E17: =IFERROR(VLOOKUP($A17, W1D1M3!$A:$F, 6, FALSE), 0) -> 0 | F17: =IFERROR(VLOOKUP($A17,#REF!, 6, FALSE), 0) -> 0 | G17: =SUM(C17:F17) -> 0 | H17: =IFERROR(RANK(G17,$G$2:$G$17,0),0) -> 4 | J17: ASFA | K17: asfasadsd | L17: 0 | M17: 0 | N17: 0 | O17: 0 | P17: 0 | Q17: 4

Sheet DAY SUMMARY W1D2
A1: TEAM ID | B1: TEAM NAME | C1: M1 | D1: M2 | E1: M3 | F1: M4 | G1: TOTAL | H1: RANK
A2: {=INDEX(TEAMLIST!A:A, ROW())} -> AWD | B2: {=INDEX(TEAMLIST!B:B, ROW())} -> Award | C2: =IFERROR(VLOOKUP($A2, W1D2M1!$A:$F, 6, FALSE), 0) -> 0 | D2: =IFERROR(VLOOKUP($A2, W1D2M2!$A:$F, 6, FALSE), 0) -> 0 | E2: =IFERROR(INDEX('DAY SUMMARY W1D1'!A:A, MATCH($A2,'DAY SUMMARY W1D1'!H:H,0)), "") | F2: =IFERROR(VLOOKUP($A2,#REF!, 6, FALSE), 0) -> 0 | G2: =SUM(C2:F2) -> 0 | H2: =IFERROR(RANK(G2,$G$2:$G$17,0),0) -> 1 | J2: {=_xlfn._xlws.SORT(A2:H17, 8, 1)} -> AWD | K2: Award | L2: 0 | M2: 0 | O2: 0 | P2: 0 | Q2: 1
A3: {=INDEX(TEAMLIST!A:A, ROW())} -> BOS | B3: {=INDEX(TEAMLIST!B:B, ROW())} -> BOSS | C3: =IFERROR(VLOOKUP($A3, W1D2M1!$A:$F, 6, FALSE), 0) -> 0 | D3: =IFERROR(VLOOKUP($A3, W1D2M2!$A:$F, 6, FALSE), 0) -> 0 | E3: =IFERROR(VLOOKUP($A3, W1D2M3!$A:$F, 6, FALSE), 0) -> 0 | F3: =IFERROR(VLOOKUP($A3,#REF!, 6, FALSE), 0) -> 0 | G3: =SUM(C3:F3) -> 0 | H3: =IFERROR(RANK(G3,$G$2:$G$17,0),0) -> 1 | J3: BOS | K3: BOSS | L3: 0 | M3: 0 | N3: 0 | O3: 0 | P3: 0 | Q3: 1
A4: {=INDEX(TEAMLIST!A:A, ROW())} -> NVD | B4: {=INDEX(TEAMLIST!B:B, ROW())} -> NerverDIe | C4: =IFERROR(VLOOKUP($A4, W1D2M1!$A:$F, 6, FALSE), 0) -> 0 | D4: =IFERROR(VLOOKUP($A4, W1D2M2!$A:$F, 6, FALSE), 0) -> 0 | E4: =IFERROR(VLOOKUP($A4, W1D2M3!$A:$F, 6, FALSE), 0) -> 0 | F4: =IFERROR(VLOOKUP($A4,#REF!, 6, FALSE), 0) -> 0 | G4: =SUM(C4:F4) -> 0 | H4: =IFERROR(RANK(G4,$G$2:$G$17,0),0) -> 1 | J4: NVD | K4: NerverDIe | L4: 0 | M4: 0 | N4: 0 | O4: 0 | P4: 0 | Q4: 1
A5: {=INDEX(TEAMLIST!A:A, ROW())} -> SBD | B5: {=INDEX(TEAMLIST!B:B, ROW())} -> Skibidy | C5: =IFERROR(VLOOKUP($A5, W1D2M1!$A:$F, 6, FALSE), 0) -> 0 | D5: =IFERROR(VLOOKUP($A5, W1D2M2!$A:$F, 6, FALSE), 0) -> 0 | E5: =IFERROR(VLOOKUP($A5, W1D2M3!$A:$F, 6, FALSE), 0) -> 0 | F5: =IFERROR(VLOOKUP($A5,#REF!, 6, FALSE), 0) -> 0 | G5: =SUM(C5:F5) -> 0 | H5: =IFERROR(RANK(G5,$G$2:$G$17,0),0) -> 1 | J5: SBD | K5: Skibidy | L5: 0 | M5: 0 | N5: 0 | O5: 0 | P5: 0 | Q5: 1
A6: {=INDEX(TEAMLIST!A:A, ROW())} -> RD | B6: {=INDEX(TEAMLIST!B:B, ROW())} -> Raddom | C6: =IFERROR(VLOOKUP($A6, W1D2M1!$A:$F, 6, FALSE), 0) -> 0 | D6: =IFERROR(VLOOKUP($A6, W1D2M2!$A:$F, 6, FALSE), 0) -> 0 | E6: =IFERROR(VLOOKUP($A6, W1D2M3!$A:$F, 6, FALSE), 0) -> 0 | F6: =IFERROR(VLOOKUP($A6,#REF!, 6, FALSE), 0) -> 0 | G6: =SUM(C6:F6) -> 0 | H6: =IFERROR(RANK(G6,$G$2:$G$17,0),0) -> 1 | J6: RD | K6: Raddom | L6: 0 | M6: 0 | N6: 0 | O6: 0 | P6: 0 | Q6: 1
A7: {=INDEX(TEAMLIST!A:A, ROW())} -> SSRS | B7: {=INDEX(TEAMLIST!B:B, ROW())} -> SaSaRaSa | C7: =IFERROR(VLOOKUP($A7, W1D2M1!$A:$F, 6, FALSE), 0) -> 0 | D7: =IFERROR(VLOOKUP($A7, W1D2M2!$A:$F, 6, FALSE), 0) -> 0 | E7: =IFERROR(VLOOKUP($A7, W1D2M3!$A:$F, 6, FALSE), 0) -> 0 | F7: =IFERROR(VLOOKUP($A7,#REF!, 6, FALSE), 0) -> 0 | G7: =SUM(C7:F7) -> 0 | H7: =IFERROR(RANK(G7,$G$2:$G$17,0),0) -> 1 | J7: SSRS | K7: SaSaRaSa | L7: 0 | M7: 0 | N7: 0 | O7: 0 | P7: 0 | Q7: 1
A8: {=INDEX(TEAMLIST!A:A, ROW())} -> OP | B8: {=INDEX(TEAMLIST!B:B, ROW())} -> Onpara | C8: =IFERROR(VLOOKUP($A8, W1D2M1!$A:$F, 6, FALSE), 0) -> 0 | D8: =IFERROR(VLOOKUP($A8, W1D2M2!$A:$F, 6, FALSE), 0) -> 0 | E8: =IFERROR(VLOOKUP($A8, W1D2M3!$A:$F, 6, FALSE), 0) -> 0 | F8: =IFERROR(VLOOKUP($A8,#REF!, 6, FALSE), 0) -> 0 | G8: =SUM(C8:F8) -> 0 | H8: =IFERROR(RANK(G8,$G$2:$G$17,0),0) -> 1 | J8: OP | K8: Onpara | L8: 0 | M8: 0 | N8: 0 | O8: 0 | P8: 0 | Q8: 1
A9: {=INDEX(TEAMLIST!A:A, ROW())} -> NX | B9: {=INDEX(TEAMLIST!B:B, ROW())} -> NoXe | C9: =IFERROR(VLOOKUP($A9, W1D2M1!$A:$F, 6, FALSE), 0) -> 0 | D9: =IFERROR(VLOOKUP($A9, W1D2M2!$A:$F, 6, FALSE), 0) -> 0 | E9: =IFERROR(VLOOKUP($A9, W1D2M3!$A:$F, 6, FALSE), 0) -> 0 | F9: =IFERROR(VLOOKUP($A9,#REF!, 6, FALSE), 0) -> 0 | G9: =SUM(C9:F9) -> 0 | H9: =IFERROR(RANK(G9,$G$2:$G$17,0),0) -> 1 | J9: NX | K9: NoXe | L9: 0 | M9: 0 | N9: 0 | O9: 0 | P9: 0 | Q9: 1
A10: {=INDEX(TEAMLIST!A:A, ROW())} -> SBZ | B10: {=INDEX(TEAMLIST!B:B, ROW())} -> SEEBRAZ | C10: =IFERROR(VLOOKUP($A10, W1D2M1!$A:$F, 6, FALSE), 0) -> 0 | D10: =IFERROR(VLOOKUP($A10, W1D2M2!$A:$F, 6, FALSE), 0) -> 0 | E10: =IFERROR(VLOOKUP($A10, W1D2M3!$A:$F, 6, FALSE), 0) -> 0 | F10: =IFERROR(VLOOKUP($A10,#REF!, 6, FALSE), 0) -> 0 | G10: =SUM(C10:F10) -> 0 | H10: =IFERROR(RANK(G10,$G$2:$G$17,0),0) -> 1 | J10: SBZ | K10: SEEBRAZ | L10: 0 | M10: 0 | N10: 0 | O10: 0 | P10: 0 | Q10: 1
A11: {=INDEX(TEAMLIST!A:A, ROW())} -> FF | B11: {=INDEX(TEAMLIST!B:B, ROW())} -> ff | C11: =IFERROR(VLOOKUP($A11, W1D2M1!$A:$F, 6, FALSE), 0) -> 0 | D11: =IFERROR(VLOOKUP($A11, W1D2M2!$A:$F, 6, FALSE), 0) -> 0 | E11: =IFERROR(VLOOKUP($A11, W1D2M3!$A:$F, 6, FALSE), 0) -> 0 | F11: =IFERROR(VLOOKUP($A11,#REF!, 6, FALSE), 0) -> 0 | G11: =SUM(C11:F11) -> 0 | H11: =IFERROR(RANK(G11,$G$2:$G$17,0),0) -> 1 | J11: FF | K11: ff | L11: 0 | M11: 0 | N11: 0 | O11: 0 | P11: 0 | Q11: 1
A12: {=INDEX(TEAMLIST!A:A, ROW())} -> SDF | B12: {=INDEX(TEAMLIST!B:B, ROW())} -> sdfsdf | C12: =IFERROR(VLOOKUP($A12, W1D2M1!$A:$F, 6, FALSE), 0) -> 0 | D12: =IFERROR(VLOOKUP($A12, W1D2M2!$A:$F, 6, FALSE), 0) -> 0 | E12: =IFERROR(VLOOKUP($A12, W1D2M3!$A:$F, 6, FALSE), 0) -> 0 | F12: =IFERROR(VLOOKUP($A12,#REF!, 6, FALSE), 0) -> 0 | G12: =SUM(C12:F12) -> 0 | H12: =IFERROR(RANK(G12,$G$2:$G$17,0),0) -> 1 | J12: SDF | K12: sdfsdf | L12: 0 | M12: 0 | N12: 0 | O12: 0 | P12: 0 | Q12: 1
A13: {=INDEX(TEAMLIST!A:A, ROW())} -> HHH | B13: {=INDEX(TEAMLIST!B:B, ROW())} -> HHHH | C13: =IFERROR(VLOOKUP($A13, W1D2M1!$A:$F, 6, FALSE), 0) -> 0 | D13: =IFERROR(VLOOKUP($A13, W1D2M2!$A:$F, 6, FALSE), 0) -> 0 | E13: =IFERROR(VLOOKUP($A13, W1D2M3!$A:$F, 6, FALSE), 0) -> 0 | F13: =IFERROR(VLOOKUP($A13,#REF!, 6, FALSE), 0) -> 0 | G13: =SUM(C13:F13) -> 0 | H13: =IFERROR(RANK(G13,$G$2:$G$17,0),0) -> 1 | J13: HHH | K13: HHHH | L13: 0 | M13: 0 | N13: 0 | O13: 0 | P13: 0 | Q13: 1
A14: {=INDEX(TEAMLIST!A:A, ROW())} -> SSEE | B14: {=INDEX(TEAMLIST!B:B, ROW())} -> SSEE | C14: =IFERROR(VLOOKUP($A14, W1D2M1!$A:$F, 6, FALSE), 0) -> 0 | D14: =IFERROR(VLOOKUP($A14, W1D2M2!$A:$F, 6, FALSE), 0) -> 0 | E14: =IFERROR(VLOOKUP($A14, W1D2M3!$A:$F, 6, FALSE), 0) -> 0 | F14: =IFERROR(VLOOKUP($A14,#REF!, 6, FALSE), 0) -> 0 | G14: =SUM(C14:F14) -> 0 | H14: =IFERROR(RANK(G14,$G$2:$G$17,0),0) -> 1 | J14: SSEE | K14: SSEE | L14: 0 | M14: 0 | N14: 0 | O14: 0 | P14: 0 | Q14: 1
... A17: {=INDEX(TEAMLIST!A:A, ROW())} -> ASFA | B17: {=INDEX(TEAMLIST!B:B, ROW())} -> asfasadsd | C17: =IFERROR(VLOOKUP($A17, W1D2M1!$A:$F, 6, FALSE), 0) -> 0 | D17: =IFERROR(VLOOKUP($A17, W1D2M2!$A:$F, 6, FALSE), 0) -> 0 | E17: =IFERROR(VLOOKUP($A17, W1D2M3!$A:$F, 6, FALSE), 0) -> 0 | F17: =IFERROR(VLOOKUP($A17,#REF!, 6, FALSE), 0) -> 0 | G17: =SUM(C17:F17) -> 0 | H17: =IFERROR(RANK(G17,$G$2:$G$17,0),0) -> 1 | J17: ASFA | K17: asfasadsd | L17: 0 | M17: 0 | N17: 0 | O17: 0 | P17: 0 | Q17: 1

Sheet DAY SUMMARY W2D1
A1: TEAM ID | B1: TEAM NAME | C1: M1 | D1: M2 | E1: M3 | F1: M4 | G1: TOTAL | H1: RANK
A2: {=INDEX(TEAMLIST!A:A, ROW())} -> AWD | B2: {=INDEX(TEAMLIST!B:B, ROW())} -> Award | C2: =IFERROR(VLOOKUP($A2, W2D1M1!$A:$F, 6, FALSE), 0) -> 0 | D2: =IFERROR(VLOOKUP($A2, W2D1M2!$A:$F, 6, FALSE), 0) -> 0 | E2: =IFERROR(VLOOKUP($A2, W2D1M3!$A:$F, 6, FALSE), 0) -> 0 | F2: =IFERROR(VLOOKUP($A2,#REF!, 6, FALSE), 0) -> 0 | G2: =SUM(C2:F2) -> 0 | H2: =IFERROR(RANK(G2,$G$2:$G$17,0),0) -> 1 | J2: {=_xlfn._xlws.SORT(A2:H17, 8, 1)} -> AWD | K2: Award | L2: 0 | M2: 0 | N2: 0 | O2: 0 | P2: 0 | Q2: 1
A3: {=INDEX(TEAMLIST!A:A, ROW())} -> BOS | B3: {=INDEX(TEAMLIST!B:B, ROW())} -> BOSS | C3: =IFERROR(VLOOKUP($A3, W2D1M1!$A:$F, 6, FALSE), 0) -> 0 | D3: =IFERROR(VLOOKUP($A3, W2D1M2!$A:$F, 6, FALSE), 0) -> 0 | E3: =IFERROR(VLOOKUP($A3, W2D1M3!$A:$F, 6, FALSE), 0) -> 0 | F3: =IFERROR(VLOOKUP($A3,#REF!, 6, FALSE), 0) -> 0 | G3: =SUM(C3:F3) -> 0 | H3: =IFERROR(RANK(G3,$G$2:$G$17,0),0) -> 1 | J3: BOS | K3: BOSS | L3: 0 | M3: 0 | N3: 0 | O3: 0 | P3: 0 | Q3: 1
A4: {=INDEX(TEAMLIST!A:A, ROW())} -> NVD | B4: {=INDEX(TEAMLIST!B:B, ROW())} -> NerverDIe | C4: =IFERROR(VLOOKUP($A4, W2D1M1!$A:$F, 6, FALSE), 0) -> 0 | D4: =IFERROR(VLOOKUP($A4, W2D1M2!$A:$F, 6, FALSE), 0) -> 0 | E4: =IFERROR(VLOOKUP($A4, W2D1M3!$A:$F, 6, FALSE), 0) -> 0 | F4: =IFERROR(VLOOKUP($A4,#REF!, 6, FALSE), 0) -> 0 | G4: =SUM(C4:F4) -> 0 | H4: =IFERROR(RANK(G4,$G$2:$G$17,0),0) -> 1 | J4: NVD | K4: NerverDIe | L4: 0 | M4: 0 | N4: 0 | O4: 0 | P4: 0 | Q4: 1
A5: {=INDEX(TEAMLIST!A:A, ROW())} -> SBD | B5: {=INDEX(TEAMLIST!B:B, ROW())} -> Skibidy | C5: =IFERROR(VLOOKUP($A5, W2D1M1!$A:$F, 6, FALSE), 0) -> 0 | D5: =IFERROR(VLOOKUP($A5, W2D1M2!$A:$F, 6, FALSE), 0) -> 0 | E5: =IFERROR(VLOOKUP($A5, W2D1M3!$A:$F, 6, FALSE), 0) -> 0 | F5: =IFERROR(VLOOKUP($A5,#REF!, 6, FALSE), 0) -> 0 | G5: =SUM(C5:F5) -> 0 | H5: =IFERROR(RANK(G5,$G$2:$G$17,0),0) -> 1 | J5: SBD | K5: Skibidy | L5: 0 | M5: 0 | N5: 0 | O5: 0 | P5: 0 | Q5: 1
A6: {=INDEX(TEAMLIST!A:A, ROW())} -> RD | B6: {=INDEX(TEAMLIST!B:B, ROW())} -> Raddom | C6: =IFERROR(VLOOKUP($A6, W2D1M1!$A:$F, 6, FALSE), 0) -> 0 | D6: =IFERROR(VLOOKUP($A6, W2D1M2!$A:$F, 6, FALSE), 0) -> 0 | E6: =IFERROR(VLOOKUP($A6, W2D1M3!$A:$F, 6, FALSE), 0) -> 0 | F6: =IFERROR(VLOOKUP($A6,#REF!, 6, FALSE), 0) -> 0 | G6: =SUM(C6:F6) -> 0 | H6: =IFERROR(RANK(G6,$G$2:$G$17,0),0) -> 1 | J6: RD | K6: Raddom | L6: 0 | M6: 0 | N6: 0 | O6: 0 | P6: 0 | Q6: 1
A7: {=INDEX(TEAMLIST!A:A, ROW())} -> SSRS | B7: {=INDEX(TEAMLIST!B:B, ROW())} -> SaSaRaSa | C7: =IFERROR(VLOOKUP($A7, W2D1M1!$A:$F, 6, FALSE), 0) -> 0 | D7: =IFERROR(VLOOKUP($A7, W2D1M2!$A:$F, 6, FALSE), 0) -> 0 | E7: =IFERROR(VLOOKUP($A7, W2D1M3!$A:$F, 6, FALSE), 0) -> 0 | F7: =IFERROR(VLOOKUP($A7,#REF!, 6, FALSE), 0) -> 0 | G7: =SUM(C7:F7) -> 0 | H7: =IFERROR(RANK(G7,$G$2:$G$17,0),0) -> 1 | J7: SSRS | K7: SaSaRaSa | L7: 0 | M7: 0 | N7: 0 | O7: 0 | P7: 0 | Q7: 1
A8: {=INDEX(TEAMLIST!A:A, ROW())} -> OP | B8: {=INDEX(TEAMLIST!B:B, ROW())} -> Onpara | C8: =IFERROR(VLOOKUP($A8, W2D1M1!$A:$F, 6, FALSE), 0) -> 0 | D8: =IFERROR(VLOOKUP($A8, W2D1M2!$A:$F, 6, FALSE), 0) -> 0 | E8: =IFERROR(VLOOKUP($A8, W2D1M3!$A:$F, 6, FALSE), 0) -> 0 | F8: =IFERROR(VLOOKUP($A8,#REF!, 6, FALSE), 0) -> 0 | G8: =SUM(C8:F8) -> 0 | H8: =IFERROR(RANK(G8,$G$2:$G$17,0),0) -> 1 | J8: OP | K8: Onpara | L8: 0 | M8: 0 | N8: 0 | O8: 0 | P8: 0 | Q8: 1
A9: {=INDEX(TEAMLIST!A:A, ROW())} -> NX | B9: {=INDEX(TEAMLIST!B:B, ROW())} -> NoXe | C9: =IFERROR(VLOOKUP($A9, W2D1M1!$A:$F, 6, FALSE), 0) -> 0 | D9: =IFERROR(VLOOKUP($A9, W2D1M2!$A:$F, 6, FALSE), 0) -> 0 | E9: =IFERROR(VLOOKUP($A9, W2D1M3!$A:$F, 6, FALSE), 0) -> 0 | F9: =IFERROR(VLOOKUP($A9,#REF!, 6, FALSE), 0) -> 0 | G9: =SUM(C9:F9) -> 0 | H9: =IFERROR(RANK(G9,$G$2:$G$17,0),0) -> 1 | J9: NX | K9: NoXe | L9: 0 | M9: 0 | N9: 0 | O9: 0 | P9: 0 | Q9: 1
A10: {=INDEX(TEAMLIST!A:A, ROW())} -> SBZ | B10: {=INDEX(TEAMLIST!B:B, ROW())} -> SEEBRAZ | C10: =IFERROR(VLOOKUP($A10, W2D1M1!$A:$F, 6, FALSE), 0) -> 0 | D10: =IFERROR(VLOOKUP($A10, W2D1M2!$A:$F, 6, FALSE), 0) -> 0 | E10: =IFERROR(VLOOKUP($A10, W2D1M3!$A:$F, 6, FALSE), 0) -> 0 | F10: =IFERROR(VLOOKUP($A10,#REF!, 6, FALSE), 0) -> 0 | G10: =SUM(C10:F10) -> 0 | H10: =IFERROR(RANK(G10,$G$2:$G$17,0),0) -> 1 | J10: SBZ | K10: SEEBRAZ | L10: 0 | M10: 0 | N10: 0 | O10: 0 | P10: 0 | Q10: 1
A11: {=INDEX(TEAMLIST!A:A, ROW())} -> FF | B11: {=INDEX(TEAMLIST!B:B, ROW())} -> ff | C11: =IFERROR(VLOOKUP($A11, W2D1M1!$A:$F, 6, FALSE), 0) -> 0 | D11: =IFERROR(VLOOKUP($A11, W2D1M2!$A:$F, 6, FALSE), 0) -> 0 | E11: =IFERROR(VLOOKUP($A11, W2D1M3!$A:$F, 6, FALSE), 0) -> 0 | F11: =IFERROR(VLOOKUP($A11,#REF!, 6, FALSE), 0) -> 0 | G11: =SUM(C11:F11) -> 0 | H11: =IFERROR(RANK(G11,$G$2:$G$17,0),0) -> 1 | J11: FF | K11: ff | L11: 0 | M11: 0 | N11: 0 | O11: 0 | P11: 0 | Q11: 1
A12: {=INDEX(TEAMLIST!A:A, ROW())} -> SDF | B12: {=INDEX(TEAMLIST!B:B, ROW())} -> sdfsdf | C12: =IFERROR(VLOOKUP($A12, W2D1M1!$A:$F, 6, FALSE), 0) -> 0 | D12: =IFERROR(VLOOKUP($A12, W2D1M2!$A:$F, 6, FALSE), 0) -> 0 | E12: =IFERROR(VLOOKUP($A12, W2D1M3!$A:$F, 6, FALSE), 0) -> 0 | F12: =IFERROR(VLOOKUP($A12,#REF!, 6, FALSE), 0) -> 0 | G12: =SUM(C12:F12) -> 0 | H12: =IFERROR(RANK(G12,$G$2:$G$17,0),0) -> 1 | J12: SDF | K12: sdfsdf | L12: 0 | M12: 0 | N12: 0 | O12: 0 | P12: 0 | Q12: 1
A13: {=INDEX(TEAMLIST!A:A, ROW())} -> HHH | B13: {=INDEX(TEAMLIST!B:B, ROW())} -> HHHH | C13: =IFERROR(VLOOKUP($A13, W2D1M1!$A:$F, 6, FALSE), 0) -> 0 | D13: =IFERROR(VLOOKUP($A13, W2D1M2!$A:$F, 6, FALSE), 0) -> 0 | E13: =IFERROR(VLOOKUP($A13, W2D1M3!$A:$F, 6, FALSE), 0) -> 0 | F13: =IFERROR(VLOOKUP($A13,#REF!, 6, FALSE), 0) -> 0 | G13: =SUM(C13:F13) -> 0 | H13: =IFERROR(RANK(G13,$G$2:$G$17,0),0) -> 1 | J13: HHH | K13: HHHH | L13: 0 | M13: 0 | N13: 0 | O13: 0 | P13: 0 | Q13: 1
A14: {=INDEX(TEAMLIST!A:A, ROW())} -> SSEE | B14: {=INDEX(TEAMLIST!B:B, ROW())} -> SSEE | C14: =IFERROR(VLOOKUP($A14, W2D1M1!$A:$F, 6, FALSE), 0) -> 0 | D14: =IFERROR(VLOOKUP($A14, W2D1M2!$A:$F, 6, FALSE), 0) -> 0 | E14: =IFERROR(VLOOKUP($A14, W2D1M3!$A:$F, 6, FALSE), 0) -> 0 | F14: =IFERROR(VLOOKUP($A14,#REF!, 6, FALSE), 0) -> 0 | G14: =SUM(C14:F14) -> 0 | H14: =IFERROR(RANK(G14,$G$2:$G$17,0),0) -> 1 | J14: SSEE | K14: SSEE | L14: 0 | M14: 0 | N14: 0 | O14: 0 | P14: 0 | Q14: 1
... A17: {=INDEX(TEAMLIST!A:A, ROW())} -> ASFA | B17: {=INDEX(TEAMLIST!B:B, ROW())} -> asfasadsd | C17: =IFERROR(VLOOKUP($A17, W2D1M1!$A:$F, 6, FALSE), 0) -> 0 | D17: =IFERROR(VLOOKUP($A17, W2D1M2!$A:$F, 6, FALSE), 0) -> 0 | E17: =IFERROR(VLOOKUP($A17, W2D1M3!$A:$F, 6, FALSE), 0) -> 0 | F17: =IFERROR(VLOOKUP($A17,#REF!, 6, FALSE), 0) -> 0 | G17: =SUM(C17:F17) -> 0 | H17: =IFERROR(RANK(G17,$G$2:$G$17,0),0) -> 1 | J17: ASFA | K17: asfasadsd | L17: 0 | M17: 0 | N17: 0 | O17: 0 | P17: 0 | Q17: 1

Sheet DAY SUMMARY W2D2
A1: TEAM ID | B1: TEAM NAME | C1: M1 | D1: M2 | E1: M3 | F1: M4 | G1: TOTAL | H1: RANK
A2: {=INDEX(TEAMLIST!A:A, ROW())} -> AWD | B2: {=INDEX(TEAMLIST!B:B, ROW())} -> Award | C2: =IFERROR(VLOOKUP($A2, W2D2M1!$A:$F, 6, FALSE), 0) -> 0 | D2: =IFERROR(VLOOKUP($A2, W2D2M2!$A:$F, 6, FALSE), 0) -> 0 | E2: =IFERROR(VLOOKUP($A2, W2D2M3!$A:$F, 6, FALSE), 0) -> 0 | F2: =IFERROR(VLOOKUP($A2,#REF!, 6, FALSE), 0) -> 0 | G2: =SUM(C2:F2) -> 0 | H2: =IFERROR(RANK(G2,$G$2:$G$17,0),0) -> 1 | J2: {=_xlfn._xlws.SORT(A2:H17, 8, 1)} -> AWD | K2: Award | L2: 0 | M2: 0 | N2: 0 | O2: 0 | P2: 0 | Q2: 1
A3: {=INDEX(TEAMLIST!A:A, ROW())} -> BOS | B3: {=INDEX(TEAMLIST!B:B, ROW())} -> BOSS | C3: =IFERROR(VLOOKUP($A3, W2D2M1!$A:$F, 6, FALSE), 0) -> 0 | D3: =IFERROR(VLOOKUP($A3, W2D2M2!$A:$F, 6, FALSE), 0) -> 0 | E3: =IFERROR(VLOOKUP($A3, W2D2M3!$A:$F, 6, FALSE), 0) -> 0 | F3: =IFERROR(VLOOKUP($A3,#REF!, 6, FALSE), 0) -> 0 | G3: =SUM(C3:F3) -> 0 | H3: =IFERROR(RANK(G3,$G$2:$G$17,0),0) -> 1 | J3: BOS | K3: BOSS | L3: 0 | M3: 0 | N3: 0 | O3: 0 | P3: 0 | Q3: 1
A4: {=INDEX(TEAMLIST!A:A, ROW())} -> NVD | B4: {=INDEX(TEAMLIST!B:B, ROW())} -> NerverDIe | C4: =IFERROR(VLOOKUP($A4, W2D2M1!$A:$F, 6, FALSE), 0) -> 0 | D4: =IFERROR(VLOOKUP($A4, W2D2M2!$A:$F, 6, FALSE), 0) -> 0 | E4: =IFERROR(VLOOKUP($A4, W2D2M3!$A:$F, 6, FALSE), 0) -> 0 | F4: =IFERROR(VLOOKUP($A4,#REF!, 6, FALSE), 0) -> 0 | G4: =SUM(C4:F4) -> 0 | H4: =IFERROR(RANK(G4,$G$2:$G$17,0),0) -> 1 | J4: NVD | K4: NerverDIe | L4: 0 | M4: 0 | N4: 0 | O4: 0 | P4: 0 | Q4: 1
A5: {=INDEX(TEAMLIST!A:A, ROW())} -> SBD | B5: {=INDEX(TEAMLIST!B:B, ROW())} -> Skibidy | C5: =IFERROR(VLOOKUP($A5, W2D2M1!$A:$F, 6, FALSE), 0) -> 0 | D5: =IFERROR(VLOOKUP($A5, W2D2M2!$A:$F, 6, FALSE), 0) -> 0 | E5: =IFERROR(VLOOKUP($A5, W2D2M3!$A:$F, 6, FALSE), 0) -> 0 | F5: =IFERROR(VLOOKUP($A5,#REF!, 6, FALSE), 0) -> 0 | G5: =SUM(C5:F5) -> 0 | H5: =IFERROR(RANK(G5,$G$2:$G$17,0),0) -> 1 | J5: SBD | K5: Skibidy | L5: 0 | M5: 0 | N5: 0 | O5: 0 | P5: 0 | Q5: 1
A6: {=INDEX(TEAMLIST!A:A, ROW())} -> RD | B6: {=INDEX(TEAMLIST!B:B, ROW())} -> Raddom | C6: =IFERROR(VLOOKUP($A6, W2D2M1!$A:$F, 6, FALSE), 0) -> 0 | D6: =IFERROR(VLOOKUP($A6, W2D2M2!$A:$F, 6, FALSE), 0) -> 0 | E6: =IFERROR(VLOOKUP($A6, W2D2M3!$A:$F, 6, FALSE), 0) -> 0 | F6: =IFERROR(VLOOKUP($A6,#REF!, 6, FALSE), 0) -> 0 | G6: =SUM(C6:F6) -> 0 | H6: =IFERROR(RANK(G6,$G$2:$G$17,0),0) -> 1 | J6: RD | K6: Raddom | L6: 0 | M6: 0 | N6: 0 | O6: 0 | P6: 0 | Q6: 1
A7: {=INDEX(TEAMLIST!A:A, ROW())} -> SSRS | B7: {=INDEX(TEAMLIST!B:B, ROW())} -> SaSaRaSa | C7: =IFERROR(VLOOKUP($A7, W2D2M1!$A:$F, 6, FALSE), 0) -> 0 | D7: =IFERROR(VLOOKUP($A7, W2D2M2!$A:$F, 6, FALSE), 0) -> 0 | E7: =IFERROR(VLOOKUP($A7, W2D2M3!$A:$F, 6, FALSE), 0) -> 0 | F7: =IFERROR(VLOOKUP($A7,#REF!, 6, FALSE), 0) -> 0 | G7: =SUM(C7:F7) -> 0 | H7: =IFERROR(RANK(G7,$G$2:$G$17,0),0) -> 1 | J7: SSRS | K7: SaSaRaSa | L7: 0 | M7: 0 | N7: 0 | O7: 0 | P7: 0 | Q7: 1
A8: {=INDEX(TEAMLIST!A:A, ROW())} -> OP | B8: {=INDEX(TEAMLIST!B:B, ROW())} -> Onpara | C8: =IFERROR(VLOOKUP($A8, W2D2M1!$A:$F, 6, FALSE), 0) -> 0 | D8: =IFERROR(VLOOKUP($A8, W2D2M2!$A:$F, 6, FALSE), 0) -> 0 | E8: =IFERROR(VLOOKUP($A8, W2D2M3!$A:$F, 6, FALSE), 0) -> 0 | F8: =IFERROR(VLOOKUP($A8,#REF!, 6, FALSE), 0) -> 0 | G8: =SUM(C8:F8) -> 0 | H8: =IFERROR(RANK(G8,$G$2:$G$17,0),0) -> 1 | J8: OP | K8: Onpara | L8: 0 | M8: 0 | N8: 0 | O8: 0 | P8: 0 | Q8: 1
A9: {=INDEX(TEAMLIST!A:A, ROW())} -> NX | B9: {=INDEX(TEAMLIST!B:B, ROW())} -> NoXe | C9: =IFERROR(VLOOKUP($A9, W2D2M1!$A:$F, 6, FALSE), 0) -> 0 | D9: =IFERROR(VLOOKUP($A9, W2D2M2!$A:$F, 6, FALSE), 0) -> 0 | E9: =IFERROR(VLOOKUP($A9, W2D2M3!$A:$F, 6, FALSE), 0) -> 0 | F9: =IFERROR(VLOOKUP($A9,#REF!, 6, FALSE), 0) -> 0 | G9: =SUM(C9:F9) -> 0 | H9: =IFERROR(RANK(G9,$G$2:$G$17,0),0) -> 1 | J9: NX | K9: NoXe | L9: 0 | M9: 0 | N9: 0 | O9: 0 | P9: 0 | Q9: 1
A10: {=INDEX(TEAMLIST!A:A, ROW())} -> SBZ | B10: {=INDEX(TEAMLIST!B:B, ROW())} -> SEEBRAZ | C10: =IFERROR(VLOOKUP($A10, W2D2M1!$A:$F, 6, FALSE), 0) -> 0 | D10: =IFERROR(VLOOKUP($A10, W2D2M2!$A:$F, 6, FALSE), 0) -> 0 | E10: =IFERROR(VLOOKUP($A10, W2D2M3!$A:$F, 6, FALSE), 0) -> 0 | F10: =IFERROR(VLOOKUP($A10,#REF!, 6, FALSE), 0) -> 0 | G10: =SUM(C10:F10) -> 0 | H10: =IFERROR(RANK(G10,$G$2:$G$17,0),0) -> 1 | J10: SBZ | K10: SEEBRAZ | L10: 0 | M10: 0 | N10: 0 | O10: 0 | P10: 0 | Q10: 1
A11: {=INDEX(TEAMLIST!A:A, ROW())} -> FF | B11: {=INDEX(TEAMLIST!B:B, ROW())} -> ff | C11: =IFERROR(VLOOKUP($A11, W2D2M1!$A:$F, 6, FALSE), 0) -> 0 | D11: =IFERROR(VLOOKUP($A11, W2D2M2!$A:$F, 6, FALSE), 0) -> 0 | E11: =IFERROR(VLOOKUP($A11, W2D2M3!$A:$F, 6, FALSE), 0) -> 0 | F11: =IFERROR(VLOOKUP($A11,#REF!, 6, FALSE), 0) -> 0 | G11: =SUM(C11:F11) -> 0 | H11: =IFERROR(RANK(G11,$G$2:$G$17,0),0) -> 1 | J11: FF | K11: ff | L11: 0 | M11: 0 | N11: 0 | O11: 0 | P11: 0 | Q11: 1
A12: {=INDEX(TEAMLIST!A:A, ROW())} -> SDF | B12: {=INDEX(TEAMLIST!B:B, ROW())} -> sdfsdf | C12: =IFERROR(VLOOKUP($A12, W2D2M1!$A:$F, 6, FALSE), 0) -> 0 | D12: =IFERROR(VLOOKUP($A12, W2D2M2!$A:$F, 6, FALSE), 0) -> 0 | E12: =IFERROR(VLOOKUP($A12, W2D2M3!$A:$F, 6, FALSE), 0) -> 0 | F12: =IFERROR(VLOOKUP($A12,#REF!, 6, FALSE), 0) -> 0 | G12: =SUM(C12:F12) -> 0 | H12: =IFERROR(RANK(G12,$G$2:$G$17,0),0) -> 1 | J12: SDF | K12: sdfsdf | L12: 0 | M12: 0 | N12: 0 | O12: 0 | P12: 0 | Q12: 1
A13: {=INDEX(TEAMLIST!A:A, ROW())} -> HHH | B13: {=INDEX(TEAMLIST!B:B, ROW())} -> HHHH | C13: =IFERROR(VLOOKUP($A13, W2D2M1!$A:$F, 6, FALSE), 0) -> 0 | D13: =IFERROR(VLOOKUP($A13, W2D2M2!$A:$F, 6, FALSE), 0) -> 0 | E13: =IFERROR(VLOOKUP($A13, W2D2M3!$A:$F, 6, FALSE), 0) -> 0 | F13: =IFERROR(VLOOKUP($A13,#REF!, 6, FALSE), 0) -> 0 | G13: =SUM(C13:F13) -> 0 | H13: =IFERROR(RANK(G13,$G$2:$G$17,0),0) -> 1 | J13: HHH | K13: HHHH | L13: 0 | M13: 0 | N13: 0 | O13: 0 | P13: 0 | Q13: 1
A14: {=INDEX(TEAMLIST!A:A, ROW())} -> SSEE | B14: {=INDEX(TEAMLIST!B:B, ROW())} -> SSEE | C14: =IFERROR(VLOOKUP($A14, W2D2M1!$A:$F, 6, FALSE), 0) -> 0 | D14: =IFERROR(VLOOKUP($A14, W2D2M2!$A:$F, 6, FALSE), 0) -> 0 | E14: =IFERROR(VLOOKUP($A14, W2D2M3!$A:$F, 6, FALSE), 0) -> 0 | F14: =IFERROR(VLOOKUP($A14,#REF!, 6, FALSE), 0) -> 0 | G14: =SUM(C14:F14) -> 0 | H14: =IFERROR(RANK(G14,$G$2:$G$17,0),0) -> 1 | J14: SSEE | K14: SSEE | L14: 0 | M14: 0 | N14: 0 | O14: 0 | P14: 0 | Q14: 1
... A17: {=INDEX(TEAMLIST!A:A, ROW())} -> ASFA | B17: {=INDEX(TEAMLIST!B:B, ROW())} -> asfasadsd | C17: =IFERROR(VLOOKUP($A17, W2D2M1!$A:$F, 6, FALSE), 0) -> 0 | D17: =IFERROR(VLOOKUP($A17, W2D2M2!$A:$F, 6, FALSE), 0) -> 0 | E17: =IFERROR(VLOOKUP($A17, W2D2M3!$A:$F, 6, FALSE), 0) -> 0 | F17: =IFERROR(VLOOKUP($A17,#REF!, 6, FALSE), 0) -> 0 | G17: =SUM(C17:F17) -> 0 | H17: =IFERROR(RANK(G17,$G$2:$G$17,0),0) -> 1 | J17: ASFA | K17: asfasadsd | L17: 0 | M17: 0 | N17: 0 | O17: 0 | P17: 0 | Q17: 1

Sheet DAY SUMMARY FINAL
A1: TEAM ID | B1: TEAM NAME | C1: M1 | D1: M2 | E1: M3 | F1: M4 | G1: TOTAL | H1: RANK
A2: {=INDEX(TEAMLIST!A:A, ROW())} -> AWD | B2: {=INDEX(TEAMLIST!B:B, ROW())} -> Award | C2: =IFERROR(VLOOKUP($A2, FinalM1!$A:$F, 6, FALSE), 0) -> 0 | D2: =IFERROR(VLOOKUP($A2, FinalM2!$A:$F, 6, FALSE), 0) -> 0 | E2: =IFERROR(VLOOKUP($A2, FinalM3!$A:$F, 6, FALSE), 0) -> 0 | F2: =IFERROR(VLOOKUP($A2,#REF!, 6, FALSE), 0) -> 0 | G2: =SUM(C2:F2) -> 0 | H2: =IFERROR(RANK(G2,$G$2:$G$17,0),0) -> 1 | J2: {=_xlfn._xlws.SORT(A2:H17, 8, 1)} -> AWD | K2: Award | L2: 0 | M2: 0 | N2: 0 | O2: 0 | P2: 0 | Q2: 1
A3: {=INDEX(TEAMLIST!A:A, ROW())} -> BOS | B3: {=INDEX(TEAMLIST!B:B, ROW())} -> BOSS | C3: =IFERROR(VLOOKUP($A3, FinalM1!$A:$F, 6, FALSE), 0) -> 0 | D3: =IFERROR(VLOOKUP($A3, FinalM2!$A:$F, 6, FALSE), 0) -> 0 | E3: =IFERROR(VLOOKUP($A3, FinalM3!$A:$F, 6, FALSE), 0) -> 0 | F3: =IFERROR(VLOOKUP($A3,#REF!, 6, FALSE), 0) -> 0 | G3: =SUM(C3:F3) -> 0 | H3: =IFERROR(RANK(G3,$G$2:$G$17,0),0) -> 1 | J3: BOS | K3: BOSS | L3: 0 | M3: 0 | N3: 0 | O3: 0 | P3: 0 | Q3: 1
A4: {=INDEX(TEAMLIST!A:A, ROW())} -> NVD | B4: {=INDEX(TEAMLIST!B:B, ROW())} -> NerverDIe | C4: =IFERROR(VLOOKUP($A4, FinalM1!$A:$F, 6, FALSE), 0) -> 0 | D4: =IFERROR(VLOOKUP($A4, FinalM2!$A:$F, 6, FALSE), 0) -> 0 | E4: =IFERROR(VLOOKUP($A4, FinalM3!$A:$F, 6, FALSE), 0) -> 0 | F4: =IFERROR(VLOOKUP($A4,#REF!, 6, FALSE), 0) -> 0 | G4: =SUM(C4:F4) -> 0 | H4: =IFERROR(RANK(G4,$G$2:$G$17,0),0) -> 1 | J4: NVD | K4: NerverDIe | L4: 0 | M4: 0 | N4: 0 | O4: 0 | P4: 0 | Q4: 1
A5: {=INDEX(TEAMLIST!A:A, ROW())} -> SBD | B5: {=INDEX(TEAMLIST!B:B, ROW())} -> Skibidy | C5: =IFERROR(VLOOKUP($A5, FinalM1!$A:$F, 6, FALSE), 0) -> 0 | D5: =IFERROR(VLOOKUP($A5, FinalM2!$A:$F, 6, FALSE), 0) -> 0 | E5: =IFERROR(VLOOKUP($A5, FinalM3!$A:$F, 6, FALSE), 0) -> 0 | F5: =IFERROR(VLOOKUP($A5,#REF!, 6, FALSE), 0) -> 0 | G5: =SUM(C5:F5) -> 0 | H5: =IFERROR(RANK(G5,$G$2:$G$17,0),0) -> 1 | J5: SBD | K5: Skibidy | L5: 0 | M5: 0 | N5: 0 | O5: 0 | P5: 0 | Q5: 1
A6: {=INDEX(TEAMLIST!A:A, ROW())} -> RD | B6: {=INDEX(TEAMLIST!B:B, ROW())} -> Raddom | C6: =IFERROR(VLOOKUP($A6, FinalM1!$A:$F, 6, FALSE), 0) -> 0 | D6: =IFERROR(VLOOKUP($A6, FinalM2!$A:$F, 6, FALSE), 0) -> 0 | E6: =IFERROR(VLOOKUP($A6, FinalM3!$A:$F, 6, FALSE), 0) -> 0 | F6: =IFERROR(VLOOKUP($A6,#REF!, 6, FALSE), 0) -> 0 | G6: =SUM(C6:F6) -> 0 | H6: =IFERROR(RANK(G6,$G$2:$G$17,0),0) -> 1 | J6: RD | K6: Raddom | L6: 0 | M6: 0 | N6: 0 | O6: 0 | P6: 0 | Q6: 1
A7: {=INDEX(TEAMLIST!A:A, ROW())} -> SSRS | B7: {=INDEX(TEAMLIST!B:B, ROW())} -> SaSaRaSa | C7: =IFERROR(VLOOKUP($A7, FinalM1!$A:$F, 6, FALSE), 0) -> 0 | D7: =IFERROR(VLOOKUP($A7, FinalM2!$A:$F, 6, FALSE), 0) -> 0 | E7: =IFERROR(VLOOKUP($A7, FinalM3!$A:$F, 6, FALSE), 0) -> 0 | F7: =IFERROR(VLOOKUP($A7,#REF!, 6, FALSE), 0) -> 0 | G7: =SUM(C7:F7) -> 0 | H7: =IFERROR(RANK(G7,$G$2:$G$17,0),0) -> 1 | J7: SSRS | K7: SaSaRaSa | L7: 0 | M7: 0 | N7: 0 | O7: 0 | P7: 0 | Q7: 1
A8: {=INDEX(TEAMLIST!A:A, ROW())} -> OP | B8: {=INDEX(TEAMLIST!B:B, ROW())} -> Onpara | C8: =IFERROR(VLOOKUP($A8, FinalM1!$A:$F, 6, FALSE), 0) -> 0 | D8: =IFERROR(VLOOKUP($A8, FinalM2!$A:$F, 6, FALSE), 0) -> 0 | E8: =IFERROR(VLOOKUP($A8, FinalM3!$A:$F, 6, FALSE), 0) -> 0 | F8: =IFERROR(VLOOKUP($A8,#REF!, 6, FALSE), 0) -> 0 | G8: =SUM(C8:F8) -> 0 | H8: =IFERROR(RANK(G8,$G$2:$G$17,0),0) -> 1 | J8: OP | K8: Onpara | L8: 0 | M8: 0 | N8: 0 | O8: 0 | P8: 0 | Q8: 1
A9: {=INDEX(TEAMLIST!A:A, ROW())} -> NX | B9: {=INDEX(TEAMLIST!B:B, ROW())} -> NoXe | C9: =IFERROR(VLOOKUP($A9, FinalM1!$A:$F, 6, FALSE), 0) -> 0 | D9: =IFERROR(VLOOKUP($A9, FinalM2!$A:$F, 6, FALSE), 0) -> 0 | E9: =IFERROR(VLOOKUP($A9, FinalM3!$A:$F, 6, FALSE), 0) -> 0 | F9: =IFERROR(VLOOKUP($A9,#REF!, 6, FALSE), 0) -> 0 | G9: =SUM(C9:F9) -> 0 | H9: =IFERROR(RANK(G9,$G$2:$G$17,0),0) -> 1 | J9: NX | K9: NoXe | L9: 0 | M9: 0 | N9: 0 | O9: 0 | P9: 0 | Q9: 1
A10: {=INDEX(TEAMLIST!A:A, ROW())} -> SBZ | B10: {=INDEX(TEAMLIST!B:B, ROW())} -> SEEBRAZ | C10: =IFERROR(VLOOKUP($A10, FinalM1!$A:$F, 6, FALSE), 0) -> 0 | D10: =IFERROR(VLOOKUP($A10, FinalM2!$A:$F, 6, FALSE), 0) -> 0 | E10: =IFERROR(VLOOKUP($A10, FinalM3!$A:$F, 6, FALSE), 0) -> 0 | F10: =IFERROR(VLOOKUP($A10,#REF!, 6, FALSE), 0) -> 0 | G10: =SUM(C10:F10) -> 0 | H10: =IFERROR(RANK(G10,$G$2:$G$17,0),0) -> 1 | J10: SBZ | K10: SEEBRAZ | L10: 0 | M10: 0 | N10: 0 | O10: 0 | P10: 0 | Q10: 1
A11: {=INDEX(TEAMLIST!A:A, ROW())} -> FF | B11: {=INDEX(TEAMLIST!B:B, ROW())} -> ff | C11: =IFERROR(VLOOKUP($A11, FinalM1!$A:$F, 6, FALSE), 0) -> 0 | D11: =IFERROR(VLOOKUP($A11, FinalM2!$A:$F, 6, FALSE), 0) -> 0 | E11: =IFERROR(VLOOKUP($A11, FinalM3!$A:$F, 6, FALSE), 0) -> 0 | F11: =IFERROR(VLOOKUP($A11,#REF!, 6, FALSE), 0) -> 0 | G11: =SUM(C11:F11) -> 0 | H11: =IFERROR(RANK(G11,$G$2:$G$17,0),0) -> 1 | J11: FF | K11: ff | L11: 0 | M11: 0 | N11: 0 | O11: 0 | P11: 0 | Q11: 1
A12: {=INDEX(TEAMLIST!A:A, ROW())} -> SDF | B12: {=INDEX(TEAMLIST!B:B, ROW())} -> sdfsdf | C12: =IFERROR(VLOOKUP($A12, FinalM1!$A:$F, 6, FALSE), 0) -> 0 | D12: =IFERROR(VLOOKUP($A12, FinalM2!$A:$F, 6, FALSE), 0) -> 0 | E12: =IFERROR(VLOOKUP($A12, FinalM3!$A:$F, 6, FALSE), 0) -> 0 | F12: =IFERROR(VLOOKUP($A12,#REF!, 6, FALSE), 0) -> 0 | G12: =SUM(C12:F12) -> 0 | H12: =IFERROR(RANK(G12,$G$2:$G$17,0),0) -> 1 | J12: SDF | K12: sdfsdf | L12: 0 | M12: 0 | N12: 0 | O12: 0 | P12: 0 | Q12: 1
A13: {=INDEX(TEAMLIST!A:A, ROW())} -> HHH | B13: {=INDEX(TEAMLIST!B:B, ROW())} -> HHHH | C13: =IFERROR(VLOOKUP($A13, FinalM1!$A:$F, 6, FALSE), 0) -> 0 | D13: =IFERROR(VLOOKUP($A13, FinalM2!$A:$F, 6, FALSE), 0) -> 0 | E13: =IFERROR(VLOOKUP($A13, FinalM3!$A:$F, 6, FALSE), 0) -> 0 | F13: =IFERROR(VLOOKUP($A13,#REF!, 6, FALSE), 0) -> 0 | G13: =SUM(C13:F13) -> 0 | H13: =IFERROR(RANK(G13,$G$2:$G$17,0),0) -> 1 | J13: HHH | K13: HHHH | L13: 0 | M13: 0 | N13: 0 | O13: 0 | P13: 0 | Q13: 1
A14: {=INDEX(TEAMLIST!A:A, ROW())} -> SSEE | B14: {=INDEX(TEAMLIST!B:B, ROW())} -> SSEE | C14: =IFERROR(VLOOKUP($A14, FinalM1!$A:$F, 6, FALSE), 0) -> 0 | D14: =IFERROR(VLOOKUP($A14, FinalM2!$A:$F, 6, FALSE), 0) -> 0 | E14: =IFERROR(VLOOKUP($A14, FinalM3!$A:$F, 6, FALSE), 0) -> 0 | F14: =IFERROR(VLOOKUP($A14,#REF!, 6, FALSE), 0) -> 0 | G14: =SUM(C14:F14) -> 0 | H14: =IFERROR(RANK(G14,$G$2:$G$17,0),0) -> 1 | J14: SSEE | K14: SSEE | L14: 0 | M14: 0 | N14: 0 | O14: 0 | P14: 0 | Q14: 1
... A17: {=INDEX(TEAMLIST!A:A, ROW())} -> ASFA | B17: {=INDEX(TEAMLIST!B:B, ROW())} -> asfasadsd | C17: =IFERROR(VLOOKUP($A17, FinalM1!$A:$F, 6, FALSE), 0) -> 0 | D17: =IFERROR(VLOOKUP($A17, FinalM2!$A:$F, 6, FALSE), 0) -> 0 | E17: =IFERROR(VLOOKUP($A17, FinalM3!$A:$F, 6, FALSE), 0) -> 0 | F17: =IFERROR(VLOOKUP($A17,#REF!, 6, FALSE), 0) -> 0 | G17: =SUM(C17:F17) -> 0 | H17: =IFERROR(RANK(G17,$G$2:$G$17,0),0) -> 1 | J17: ASFA | K17: asfasadsd | L17: 0 | M17: 0 | N17: 0 | O17: 0 | P17: 0 | Q17: 1

Sheet WEEK SUMMARY W1
A1: TEAM ID | B1: TEAM NAME | C1: DAY1 | D1: DAY2 | E1: TOTAL WEEK | F1: RANK
A2: {=INDEX(TEAMLIST!A:A, ROW())} -> AWD | B2: {=INDEX(TEAMLIST!B:B, ROW())} -> Award | C2: =IFERROR(VLOOKUP($A2,'DAY SUMMARY W1D1'!$A:$G,7,FALSE),0) -> 1 | D2: =IFERROR(VLOOKUP($A2,'DAY SUMMARY W1D2'!$A:$G,7,FALSE),0) -> 0 | E2: =SUM(C2:D2) -> 1 | F2: =IFERROR(RANK(E2,$E$2:$E$17,0),0) -> 3 | H2: {=_xlfn._xlws.SORT(A2:F17, 6, 1)} -> RR | I2: rr | J2: 5 | K2: 0 | L2: 5 | M2: 1
A3: {=INDEX(TEAMLIST!A:A, ROW())} -> BOS | B3: {=INDEX(TEAMLIST!B:B, ROW())} -> BOSS | C3: =IFERROR(VLOOKUP($A3,'DAY SUMMARY W1D1'!$A:$G,7,FALSE),0) -> 0 | D3: =IFERROR(VLOOKUP($A3,'DAY SUMMARY W1D2'!$A:$G,7,FALSE),0) -> 0 | E3: =SUM(C3:D3) -> 0 | F3: =IFERROR(RANK(E3,$E$2:$E$17,0),0) -> 4 | H3: RD | I3: Raddom | J3: 3 | K3: 0 | L3: 3 | M3: 2
A4: {=INDEX(TEAMLIST!A:A, ROW())} -> NVD | B4: {=INDEX(TEAMLIST!B:B, ROW())} -> NerverDIe | C4: =IFERROR(VLOOKUP($A4,'DAY SUMMARY W1D1'!$A:$G,7,FALSE),0) -> 0 | D4: =IFERROR(VLOOKUP($A4,'DAY SUMMARY W1D2'!$A:$G,7,FALSE),0) -> 0 | E4: =SUM(C4:D4) -> 0 | F4: =IFERROR(RANK(E4,$E$2:$E$17,0),0) -> 4 | H4: AWD | I4: Award | J4: 1 | K4: 0 | L4: 1 | M4: 3
A5: {=INDEX(TEAMLIST!A:A, ROW())} -> SBD | B5: {=INDEX(TEAMLIST!B:B, ROW())} -> Skibidy | C5: =IFERROR(VLOOKUP($A5,'DAY SUMMARY W1D1'!$A:$G,7,FALSE),0) -> 0 | D5: =IFERROR(VLOOKUP($A5,'DAY SUMMARY W1D2'!$A:$G,7,FALSE),0) -> 0 | E5: =SUM(C5:D5) -> 0 | F5: =IFERROR(RANK(E5,$E$2:$E$17,0),0) -> 4 | H5: BOS | I5: BOSS | J5: 0 | K5: 0 | L5: 0 | M5: 4
A6: {=INDEX(TEAMLIST!A:A, ROW())} -> RD | B6: {=INDEX(TEAMLIST!B:B, ROW())} -> Raddom | C6: =IFERROR(VLOOKUP($A6,'DAY SUMMARY W1D1'!$A:$G,7,FALSE),0) -> 3 | D6: =IFERROR(VLOOKUP($A6,'DAY SUMMARY W1D2'!$A:$G,7,FALSE),0) -> 0 | E6: =SUM(C6:D6) -> 3 | F6: =IFERROR(RANK(E6,$E$2:$E$17,0),0) -> 2 | H6: NVD | I6: NerverDIe | J6: 0 | K6: 0 | L6: 0 | M6: 4
A7: {=INDEX(TEAMLIST!A:A, ROW())} -> SSRS | B7: {=INDEX(TEAMLIST!B:B, ROW())} -> SaSaRaSa | C7: =IFERROR(VLOOKUP($A7,'DAY SUMMARY W1D1'!$A:$G,7,FALSE),0) -> 0 | D7: =IFERROR(VLOOKUP($A7,'DAY SUMMARY W1D2'!$A:$G,7,FALSE),0) -> 0 | E7: =SUM(C7:D7) -> 0 | F7: =IFERROR(RANK(E7,$E$2:$E$17,0),0) -> 4 | H7: SBD | I7: Skibidy | J7: 0 | K7: 0 | L7: 0 | M7: 4
A8: {=INDEX(TEAMLIST!A:A, ROW())} -> OP | B8: {=INDEX(TEAMLIST!B:B, ROW())} -> Onpara | C8: =IFERROR(VLOOKUP($A8,'DAY SUMMARY W1D1'!$A:$G,7,FALSE),0) -> 0 | D8: =IFERROR(VLOOKUP($A8,'DAY SUMMARY W1D2'!$A:$G,7,FALSE),0) -> 0 | E8: =SUM(C8:D8) -> 0 | F8: =IFERROR(RANK(E8,$E$2:$E$17,0),0) -> 4 | H8: SSRS | I8: SaSaRaSa | J8: 0 | K8: 0 | L8: 0 | M8: 4
A9: {=INDEX(TEAMLIST!A:A, ROW())} -> NX | B9: {=INDEX(TEAMLIST!B:B, ROW())} -> NoXe | C9: =IFERROR(VLOOKUP($A9,'DAY SUMMARY W1D1'!$A:$G,7,FALSE),0) -> 0 | D9: =IFERROR(VLOOKUP($A9,'DAY SUMMARY W1D2'!$A:$G,7,FALSE),0) -> 0 | E9: =SUM(C9:D9) -> 0 | F9: =IFERROR(RANK(E9,$E$2:$E$17,0),0) -> 4 | H9: OP | I9: Onpara | J9: 0 | K9: 0 | L9: 0 | M9: 4
A10: {=INDEX(TEAMLIST!A:A, ROW())} -> SBZ | B10: {=INDEX(TEAMLIST!B:B, ROW())} -> SEEBRAZ | C10: =IFERROR(VLOOKUP($A10,'DAY SUMMARY W1D1'!$A:$G,7,FALSE),0) -> 0 | D10: =IFERROR(VLOOKUP($A10,'DAY SUMMARY W1D2'!$A:$G,7,FALSE),0) -> 0 | E10: =SUM(C10:D10) -> 0 | F10: =IFERROR(RANK(E10,$E$2:$E$17,0),0) -> 4 | H10: NX | I10: NoXe | J10: 0 | K10: 0 | L10: 0 | M10: 4
A11: {=INDEX(TEAMLIST!A:A, ROW())} -> FF | B11: {=INDEX(TEAMLIST!B:B, ROW())} -> ff | C11: =IFERROR(VLOOKUP($A11,'DAY SUMMARY W1D1'!$A:$G,7,FALSE),0) -> 0 | D11: =IFERROR(VLOOKUP($A11,'DAY SUMMARY W1D2'!$A:$G,7,FALSE),0) -> 0 | E11: =SUM(C11:D11) -> 0 | F11: =IFERROR(RANK(E11,$E$2:$E$17,0),0) -> 4 | H11: SBZ | I11: SEEBRAZ | J11: 0 | K11: 0 | L11: 0 | M11: 4
A12: {=INDEX(TEAMLIST!A:A, ROW())} -> SDF | B12: {=INDEX(TEAMLIST!B:B, ROW())} -> sdfsdf | C12: =IFERROR(VLOOKUP($A12,'DAY SUMMARY W1D1'!$A:$G,7,FALSE),0) -> 0 | D12: =IFERROR(VLOOKUP($A12,'DAY SUMMARY W1D2'!$A:$G,7,FALSE),0) -> 0 | E12: =SUM(C12:D12) -> 0 | F12: =IFERROR(RANK(E12,$E$2:$E$17,0),0) -> 4 | H12: FF | I12: ff | J12: 0 | K12: 0 | L12: 0 | M12: 4
A13: {=INDEX(TEAMLIST!A:A, ROW())} -> HHH | B13: {=INDEX(TEAMLIST!B:B, ROW())} -> HHHH | C13: =IFERROR(VLOOKUP($A13,'DAY SUMMARY W1D1'!$A:$G,7,FALSE),0) -> 0 | D13: =IFERROR(VLOOKUP($A13,'DAY SUMMARY W1D2'!$A:$G,7,FALSE),0) -> 0 | E13: =SUM(C13:D13) -> 0 | F13: =IFERROR(RANK(E13,$E$2:$E$17,0),0) -> 4 | H13: SDF | I13: sdfsdf | J13: 0 | K13: 0 | L13: 0 | M13: 4
A14: {=INDEX(TEAMLIST!A:A, ROW())} -> SSEE | B14: {=INDEX(TEAMLIST!B:B, ROW())} -> SSEE | C14: =IFERROR(VLOOKUP($A14,'DAY SUMMARY W1D1'!$A:$G,7,FALSE),0) -> 0 | D14: =IFERROR(VLOOKUP($A14,'DAY SUMMARY W1D2'!$A:$G,7,FALSE),0) -> 0 | E14: =SUM(C14:D14) -> 0 | F14: =IFERROR(RANK(E14,$E$2:$E$17,0),0) -> 4 | H14: HHH | I14: HHHH | J14: 0 | K14: 0 | L14: 0 | M14: 4
... A17: {=INDEX(TEAMLIST!A:A, ROW())} -> ASFA | B17: {=INDEX(TEAMLIST!B:B, ROW())} -> asfasadsd | C17: =IFERROR(VLOOKUP($A17,'DAY SUMMARY W1D1'!$A:$G,7,FALSE),0) -> 0 | D17: =IFERROR(VLOOKUP($A17,'DAY SUMMARY W1D2'!$A:$G,7,FALSE),0) -> 0 | E17: =SUM(C17:D17) -> 0 | F17: =IFERROR(RANK(E17,$E$2:$E$17,0),0) -> 4 | H17: ASFA | I17: asfasadsd | J17: 0 | K17: 0 | L17: 0 | M17: 4

Sheet WEEK SUMMARY W2
A1: TEAM ID | B1: TEAM NAME | C1: DAY1 | D1: DAY2 | E1: TOTAL WEEK | F1: RANK
A2: {=INDEX(TEAMLIST!A:A, ROW())} -> AWD | B2: {=INDEX(TEAMLIST!B:B, ROW())} -> Award | C2: =IFERROR(VLOOKUP($A2,'DAY SUMMARY W2D1'!$A:$G,7,FALSE),0) -> 0 | D2: =IFERROR(VLOOKUP($A2,'DAY SUMMARY W2D2'!$A:$G,7,FALSE),0) -> 0 | E2: =SUM(C2:D2) -> 0 | F2: =IFERROR(RANK(E2,$E$2:$E$17,0),0) -> 1 | H2: {=_xlfn._xlws.SORT(A2:F17, 6, 1)} -> AWD | I2: Award | J2: 0 | K2: 0 | L2: 0 | M2: 1
A3: {=INDEX(TEAMLIST!A:A, ROW())} -> BOS | B3: {=INDEX(TEAMLIST!B:B, ROW())} -> BOSS | C3: =IFERROR(VLOOKUP($A3,'DAY SUMMARY W2D1'!$A:$G,7,FALSE),0) -> 0 | D3: =IFERROR(VLOOKUP($A3,'DAY SUMMARY W2D2'!$A:$G,7,FALSE),0) -> 0 | E3: =SUM(C3:D3) -> 0 | F3: =IFERROR(RANK(E3,$E$2:$E$17,0),0) -> 1 | H3: BOS | I3: BOSS | J3: 0 | K3: 0 | L3: 0 | M3: 1
A4: {=INDEX(TEAMLIST!A:A, ROW())} -> NVD | B4: {=INDEX(TEAMLIST!B:B, ROW())} -> NerverDIe | C4: =IFERROR(VLOOKUP($A4,'DAY SUMMARY W2D1'!$A:$G,7,FALSE),0) -> 0 | D4: =IFERROR(VLOOKUP($A4,'DAY SUMMARY W2D2'!$A:$G,7,FALSE),0) -> 0 | E4: =SUM(C4:D4) -> 0 | F4: =IFERROR(RANK(E4,$E$2:$E$17,0),0) -> 1 | H4: NVD | I4: NerverDIe | J4: 0 | K4: 0 | L4: 0 | M4: 1
A5: {=INDEX(TEAMLIST!A:A, ROW())} -> SBD | B5: {=INDEX(TEAMLIST!B:B, ROW())} -> Skibidy | C5: =IFERROR(VLOOKUP($A5,'DAY SUMMARY W2D1'!$A:$G,7,FALSE),0) -> 0 | D5: =IFERROR(VLOOKUP($A5,'DAY SUMMARY W2D2'!$A:$G,7,FALSE),0) -> 0 | E5: =SUM(C5:D5) -> 0 | F5: =IFERROR(RANK(E5,$E$2:$E$17,0),0) -> 1 | H5: SBD | I5: Skibidy | J5: 0 | K5: 0 | L5: 0 | M5: 1
A6: {=INDEX(TEAMLIST!A:A, ROW())} -> RD | B6: {=INDEX(TEAMLIST!B:B, ROW())} -> Raddom | C6: =IFERROR(VLOOKUP($A6,'DAY SUMMARY W2D1'!$A:$G,7,FALSE),0) -> 0 | D6: =IFERROR(VLOOKUP($A6,'DAY SUMMARY W2D2'!$A:$G,7,FALSE),0) -> 0 | E6: =SUM(C6:D6) -> 0 | F6: =IFERROR(RANK(E6,$E$2:$E$17,0),0) -> 1 | H6: RD | I6: Raddom | J6: 0 | K6: 0 | L6: 0 | M6: 1
A7: {=INDEX(TEAMLIST!A:A, ROW())} -> SSRS | B7: {=INDEX(TEAMLIST!B:B, ROW())} -> SaSaRaSa | C7: =IFERROR(VLOOKUP($A7,'DAY SUMMARY W2D1'!$A:$G,7,FALSE),0) -> 0 | D7: =IFERROR(VLOOKUP($A7,'DAY SUMMARY W2D2'!$A:$G,7,FALSE),0) -> 0 | E7: =SUM(C7:D7) -> 0 | F7: =IFERROR(RANK(E7,$E$2:$E$17,0),0) -> 1 | H7: SSRS | I7: SaSaRaSa | J7: 0 | K7: 0 | L7: 0 | M7: 1
A8: {=INDEX(TEAMLIST!A:A, ROW())} -> OP | B8: {=INDEX(TEAMLIST!B:B, ROW())} -> Onpara | C8: =IFERROR(VLOOKUP($A8,'DAY SUMMARY W2D1'!$A:$G,7,FALSE),0) -> 0 | D8: =IFERROR(VLOOKUP($A8,'DAY SUMMARY W2D2'!$A:$G,7,FALSE),0) -> 0 | E8: =SUM(C8:D8) -> 0 | F8: =IFERROR(RANK(E8,$E$2:$E$17,0),0) -> 1 | H8: OP | I8: Onpara | J8: 0 | K8: 0 | L8: 0 | M8: 1
A9: {=INDEX(TEAMLIST!A:A, ROW())} -> NX | B9: {=INDEX(TEAMLIST!B:B, ROW())} -> NoXe | C9: =IFERROR(VLOOKUP($A9,'DAY SUMMARY W2D1'!$A:$G,7,FALSE),0) -> 0 | D9: =IFERROR(VLOOKUP($A9,'DAY SUMMARY W2D2'!$A:$G,7,FALSE),0) -> 0 | E9: =SUM(C9:D9) -> 0 | F9: =IFERROR(RANK(E9,$E$2:$E$17,0),0) -> 1 | H9: NX | I9: NoXe | J9: 0 | K9: 0 | L9: 0 | M9: 1
A10: {=INDEX(TEAMLIST!A:A, ROW())} -> SBZ | B10: {=INDEX(TEAMLIST!B:B, ROW())} -> SEEBRAZ | C10: =IFERROR(VLOOKUP($A10,'DAY SUMMARY W2D1'!$A:$G,7,FALSE),0) -> 0 | D10: =IFERROR(VLOOKUP($A10,'DAY SUMMARY W2D2'!$A:$G,7,FALSE),0) -> 0 | E10: =SUM(C10:D10) -> 0 | F10: =IFERROR(RANK(E10,$E$2:$E$17,0),0) -> 1 | H10: SBZ | I10: SEEBRAZ | J10: 0 | K10: 0 | L10: 0 | M10: 1
A11: {=INDEX(TEAMLIST!A:A, ROW())} -> FF | B11: {=INDEX(TEAMLIST!B:B, ROW())} -> ff | C11: =IFERROR(VLOOKUP($A11,'DAY SUMMARY W2D1'!$A:$G,7,FALSE),0) -> 0 | D11: =IFERROR(VLOOKUP($A11,'DAY SUMMARY W2D2'!$A:$G,7,FALSE),0) -> 0 | E11: =SUM(C11:D11) -> 0 | F11: =IFERROR(RANK(E11,$E$2:$E$17,0),0) -> 1 | H11: FF | I11: ff | J11: 0 | K11: 0 | L11: 0 | M11: 1
A12: {=INDEX(TEAMLIST!A:A, ROW())} -> SDF | B12: {=INDEX(TEAMLIST!B:B, ROW())} -> sdfsdf | C12: =IFERROR(VLOOKUP($A12,'DAY SUMMARY W2D1'!$A:$G,7,FALSE),0) -> 0 | D12: =IFERROR(VLOOKUP($A12,'DAY SUMMARY W2D2'!$A:$G,7,FALSE),0) -> 0 | E12: =SUM(C12:D12) -> 0 | F12: =IFERROR(RANK(E12,$E$2:$E$17,0),0) -> 1 | H12: SDF | I12: sdfsdf | J12: 0 | K12: 0 | L12: 0 | M12: 1
A13: {=INDEX(TEAMLIST!A:A, ROW())} -> HHH | B13: {=INDEX(TEAMLIST!B:B, ROW())} -> HHHH | C13: =IFERROR(VLOOKUP($A13,'DAY SUMMARY W2D1'!$A:$G,7,FALSE),0) -> 0 | D13: =IFERROR(VLOOKUP($A13,'DAY SUMMARY W2D2'!$A:$G,7,FALSE),0) -> 0 | E13: =SUM(C13:D13) -> 0 | F13: =IFERROR(RANK(E13,$E$2:$E$17,0),0) -> 1 | H13: HHH | I13: HHHH | J13: 0 | K13: 0 | L13: 0 | M13: 1
A14: {=INDEX(TEAMLIST!A:A, ROW())} -> SSEE | B14: {=INDEX(TEAMLIST!B:B, ROW())} -> SSEE | C14: =IFERROR(VLOOKUP($A14,'DAY SUMMARY W2D1'!$A:$G,7,FALSE),0) -> 0 | D14: =IFERROR(VLOOKUP($A14,'DAY SUMMARY W2D2'!$A:$G,7,FALSE),0) -> 0 | E14: =SUM(C14:D14) -> 0 | F14: =IFERROR(RANK(E14,$E$2:$E$17,0),0) -> 1 | H14: SSEE | I14: SSEE | J14: 0 | K14: 0 | L14: 0 | M14: 1
... A17: {=INDEX(TEAMLIST!A:A, ROW())} -> ASFA | B17: {=INDEX(TEAMLIST!B:B, ROW())} -> asfasadsd | C17: =IFERROR(VLOOKUP($A17,'DAY SUMMARY W2D1'!$A:$G,7,FALSE),0) -> 0 | D17: =IFERROR(VLOOKUP($A17,'DAY SUMMARY W2D2'!$A:$G,7,FALSE),0) -> 0 | E17: =SUM(C17:D17) -> 0 | F17: =IFERROR(RANK(E17,$E$2:$E$17,0),0) -> 1 | H17: ASFA | I17: asfasadsd | J17: 0 | K17: 0 | L17: 0 | M17: 1

Sheet OVERALL SUMMARY
A1: TEAM ID | B1: TEAM NAME | C1: WEEK1 | D1: WEEK2 | E1: FINAL | F1: TOTAL OVERALL | G1: RANK
A2: {=INDEX(TEAMLIST!A:A, ROW())} -> AWD | B2: {=INDEX(TEAMLIST!B:B, ROW())} -> Award | C2: =IFERROR(VLOOKUP($A2,'WEEK SUMMARY W1'!$A:$E,5,FALSE),0) -> 1 | D2: =IFERROR(VLOOKUP($A2,'WEEK SUMMARY W2'!$A:$E,5,FALSE),0) -> 0 | E2: =IFERROR(VLOOKUP($A2,'DAY SUMMARY FINAL'!$A:$G,7,FALSE),0) -> 0 | F2: =SUM(C2:E2) -> 1 | G2: =RANK(F2,$F$2:$F$17,0) -> 3 | I2: {=_xlfn._xlws.SORT(A2:G17, 7, 1)} -> RR | J2: rr | K2: 5 | L2: 0 | M2: 0 | N2: 5 | O2: 1
A3: {=INDEX(TEAMLIST!A:A, ROW())} -> BOS | B3: {=INDEX(TEAMLIST!B:B, ROW())} -> BOSS | C3: =IFERROR(VLOOKUP($A3,'WEEK SUMMARY W1'!$A:$E,5,FALSE),0) -> 0 | D3: =IFERROR(VLOOKUP($A3,'WEEK SUMMARY W2'!$A:$E,5,FALSE),0) -> 0 | E3: =IFERROR(VLOOKUP($A3,'DAY SUMMARY FINAL'!$A:$G,7,FALSE),0) -> 0 | F3: =SUM(C3:E3) -> 0 | G3: =RANK(F3,$F$2:$F$17,0) -> 4 | I3: RD | J3: Raddom | K3: 3 | L3: 0 | M3: 0 | N3: 3 | O3: 2
A4: {=INDEX(TEAMLIST!A:A, ROW())} -> NVD | B4: {=INDEX(TEAMLIST!B:B, ROW())} -> NerverDIe | C4: =IFERROR(VLOOKUP($A4,'WEEK SUMMARY W1'!$A:$E,5,FALSE),0) -> 0 | D4: =IFERROR(VLOOKUP($A4,'WEEK SUMMARY W2'!$A:$E,5,FALSE),0) -> 0 | E4: =IFERROR(VLOOKUP($A4,'DAY SUMMARY FINAL'!$A:$G,7,FALSE),0) -> 0 | F4: =SUM(C4:E4) -> 0 | G4: =RANK(F4,$F$2:$F$17,0) -> 4 | I4: AWD | J4: Award | K4: 1 | L4: 0 | M4: 0 | N4: 1 | O4: 3
A5: {=INDEX(TEAMLIST!A:A, ROW())} -> SBD | B5: {=INDEX(TEAMLIST!B:B, ROW())} -> Skibidy | C5: =IFERROR(VLOOKUP($A5,'WEEK SUMMARY W1'!$A:$E,5,FALSE),0) -> 0 | D5: =IFERROR(VLOOKUP($A5,'WEEK SUMMARY W2'!$A:$E,5,FALSE),0) -> 0 | E5: =IFERROR(VLOOKUP($A5,'DAY SUMMARY FINAL'!$A:$G,7,FALSE),0) -> 0 | F5: =SUM(C5:E5) -> 0 | G5: =RANK(F5,$F$2:$F$17,0) -> 4 | I5: BOS | J5: BOSS | K5: 0 | L5: 0 | M5: 0 | N5: 0 | O5: 4
A6: {=INDEX(TEAMLIST!A:A, ROW())} -> RD | B6: {=INDEX(TEAMLIST!B:B, ROW())} -> Raddom | C6: =IFERROR(VLOOKUP($A6,'WEEK SUMMARY W1'!$A:$E,5,FALSE),0) -> 3 | D6: =IFERROR(VLOOKUP($A6,'WEEK SUMMARY W2'!$A:$E,5,FALSE),0) -> 0 | E6: =IFERROR(VLOOKUP($A6,'DAY SUMMARY FINAL'!$A:$G,7,FALSE),0) -> 0 | F6: =SUM(C6:E6) -> 3 | G6: =RANK(F6,$F$2:$F$17,0) -> 2 | I6: NVD | J6: NerverDIe | K6: 0 | L6: 0 | M6: 0 | N6: 0 | O6: 4
A7: {=INDEX(TEAMLIST!A:A, ROW())} -> SSRS | B7: {=INDEX(TEAMLIST!B:B, ROW())} -> SaSaRaSa | C7: =IFERROR(VLOOKUP($A7,'WEEK SUMMARY W1'!$A:$E,5,FALSE),0) -> 0 | D7: =IFERROR(VLOOKUP($A7,'WEEK SUMMARY W2'!$A:$E,5,FALSE),0) -> 0 | E7: =IFERROR(VLOOKUP($A7,'DAY SUMMARY FINAL'!$A:$G,7,FALSE),0) -> 0 | F7: =SUM(C7:E7) -> 0 | G7: =RANK(F7,$F$2:$F$17,0) -> 4 | I7: SBD | J7: Skibidy | K7: 0 | L7: 0 | M7: 0 | N7: 0 | O7: 4
A8: {=INDEX(TEAMLIST!A:A, ROW())} -> OP | B8: {=INDEX(TEAMLIST!B:B, ROW())} -> Onpara | C8: =IFERROR(VLOOKUP($A8,'WEEK SUMMARY W1'!$A:$E,5,FALSE),0) -> 0 | D8: =IFERROR(VLOOKUP($A8,'WEEK SUMMARY W2'!$A:$E,5,FALSE),0) -> 0 | E8: =IFERROR(VLOOKUP($A8,'DAY SUMMARY FINAL'!$A:$G,7,FALSE),0) -> 0 | F8: =SUM(C8:E8) -> 0 | G8: =RANK(F8,$F$2:$F$17,0) -> 4 | I8: SSRS | J8: SaSaRaSa | K8: 0 | L8: 0 | M8: 0 | N8: 0 | O8: 4
A9: {=INDEX(TEAMLIST!A:A, ROW())} -> NX | B9: {=INDEX(TEAMLIST!B:B, ROW())} -> NoXe | C9: =IFERROR(VLOOKUP($A9,'WEEK SUMMARY W1'!$A:$E,5,FALSE),0) -> 0 | D9: =IFERROR(VLOOKUP($A9,'WEEK SUMMARY W2'!$A:$E,5,FALSE),0) -> 0 | E9: =IFERROR(VLOOKUP($A9,'DAY SUMMARY FINAL'!$A:$G,7,FALSE),0) -> 0 | F9: =SUM(C9:E9) -> 0 | G9: =RANK(F9,$F$2:$F$17,0) -> 4 | I9: OP | J9: Onpara | K9: 0 | L9: 0 | M9: 0 | N9: 0 | O9: 4
A10: {=INDEX(TEAMLIST!A:A, ROW())} -> SBZ | B10: {=INDEX(TEAMLIST!B:B, ROW())} -> SEEBRAZ | C10: =IFERROR(VLOOKUP($A10,'WEEK SUMMARY W1'!$A:$E,5,FALSE),0) -> 0 | D10: =IFERROR(VLOOKUP($A10,'WEEK SUMMARY W2'!$A:$E,5,FALSE),0) -> 0 | E10: =IFERROR(VLOOKUP($A10,'DAY SUMMARY FINAL'!$A:$G,7,FALSE),0) -> 0 | F10: =SUM(C10:E10) -> 0 | G10: =RANK(F10,$F$2:$F$17,0) -> 4 | I10: NX | J10: NoXe | K10: 0 | L10: 0 | M10: 0 | N10: 0 | O10: 4
A11: {=INDEX(TEAMLIST!A:A, ROW())} -> FF | B11: {=INDEX(TEAMLIST!B:B, ROW())} -> ff | C11: =IFERROR(VLOOKUP($A11,'WEEK SUMMARY W1'!$A:$E,5,FALSE),0) -> 0 | D11: =IFERROR(VLOOKUP($A11,'WEEK SUMMARY W2'!$A:$E,5,FALSE),0) -> 0 | E11: =IFERROR(VLOOKUP($A11,'DAY SUMMARY FINAL'!$A:$G,7,FALSE),0) -> 0 | F11: =SUM(C11:E11) -> 0 | G11: =RANK(F11,$F$2:$F$17,0) -> 4 | I11: SBZ | J11: SEEBRAZ | K11: 0 | L11: 0 | M11: 0 | N11: 0 | O11: 4
A12: {=INDEX(TEAMLIST!A:A, ROW())} -> SDF | B12: {=INDEX(TEAMLIST!B:B, ROW())} -> sdfsdf | C12: =IFERROR(VLOOKUP($A12,'WEEK SUMMARY W1'!$A:$E,5,FALSE),0) -> 0 | D12: =IFERROR(VLOOKUP($A12,'WEEK SUMMARY W2'!$A:$E,5,FALSE),0) -> 0 | E12: =IFERROR(VLOOKUP($A12,'DAY SUMMARY FINAL'!$A:$G,7,FALSE),0) -> 0 | F12: =SUM(C12:E12) -> 0 | G12: =RANK(F12,$F$2:$F$17,0) -> 4 | I12: FF | J12: ff | K12: 0 | L12: 0 | M12: 0 | N12: 0 | O12: 4
A13: {=INDEX(TEAMLIST!A:A, ROW())} -> HHH | B13: {=INDEX(TEAMLIST!B:B, ROW())} -> HHHH | C13: =IFERROR(VLOOKUP($A13,'WEEK SUMMARY W1'!$A:$E,5,FALSE),0) -> 0 | D13: =IFERROR(VLOOKUP($A13,'WEEK SUMMARY W2'!$A:$E,5,FALSE),0) -> 0 | E13: =IFERROR(VLOOKUP($A13,'DAY SUMMARY FINAL'!$A:$G,7,FALSE),0) -> 0 | F13: =SUM(C13:E13) -> 0 | G13: =RANK(F13,$F$2:$F$17,0) -> 4 | I13: SDF | J13: sdfsdf | K13: 0 | L13: 0 | M13: 0 | N13: 0 | O13: 4
A14: {=INDEX(TEAMLIST!A:A, ROW())} -> SSEE | B14: {=INDEX(TEAMLIST!B:B, ROW())} -> SSEE | C14: =IFERROR(VLOOKUP($A14,'WEEK SUMMARY W1'!$A:$E,5,FALSE),0) -> 0 | D14: =IFERROR(VLOOKUP($A14,'WEEK SUMMARY W2'!$A:$E,5,FALSE),0) -> 0 | E14: =IFERROR(VLOOKUP($A14,'DAY SUMMARY FINAL'!$A:$G,7,FALSE),0) -> 0 | F14: =SUM(C14:E14) -> 0 | G14: =RANK(F14,$F$2:$F$17,0) -> 4 | I14: HHH | J14: HHHH | K14: 0 | L14: 0 | M14: 0 | N14: 0 | O14: 4
... A17: {=INDEX(TEAMLIST!A:A, ROW())} -> ASFA | B17: {=INDEX(TEAMLIST!B:B, ROW())} -> asfasadsd | C17: =IFERROR(VLOOKUP($A17,'WEEK SUMMARY W1'!$A:$E,5,FALSE),0) -> 0 | D17: =IFERROR(VLOOKUP($A17,'WEEK SUMMARY W2'!$A:$E,5,FALSE),0) -> 0 | E17: =IFERROR(VLOOKUP($A17,'DAY SUMMARY FINAL'!$A:$G,7,FALSE),0) -> 0 | F17: =SUM(C17:E17) -> 0 | G17: =RANK(F17,$F$2:$F$17,0) -> 4 | I17: ASFA | J17: asfasadsd | K17: 0 | L17: 0 | M17: 0 | N17: 0 | O17: 4

Sheet W1D1M1
A1: TEAM TAG | B1: TEAM NAME | C1: RANK | D1: KILL | E1: RANK POINT | F1: TOTAL POINT
